Workbook
Name DvListSource1: [1]Sheet2!$J$1:$J$708
Name DvListSource2: [1]Sheet2!$M$1:$M$2143

Sheet Master list
B1: CARRIER - PTT Master List
C2: 1 | D2: =C2+1 -> 2 | E2: =D2+1 -> 3 | F2: =E2+1 -> 4 | G2: =F2+1 -> 5 | H2: =G2+1 -> 6 | I2: =H2+1 -> 7 | J2: =I2+1 -> 8 | K2: =J2+1 -> 9 | ... M2: =L2+1 -> 11
B3: Vendor | C3: Material | D3: Description | E3: Grade | F3: Coating | H3: T | I3: W | J3: L | K3: Weight/PC | L3: Type | M3: Delivery to | O3: Master width
B4: LP0047 | C4: G0011030001487E | D4: SGCC-ZSBX-Z08 : 0.5*80*730 CHR-FREE | E4: =LEFT(G4,4) -> SGCC | F4: =RIGHT(G4,3) -> Z08 | G4: SGCC-ZSBX-Z08 | H4: 0.5 | I4: 80 | J4: 730 | K4: =IF(J4="Coil",1,7.85*H4*I4*J4/10^6) -> 0.22922 | L4: =IF(J4="Coil","KG,","Pcs") -> Pcs | M4: 0 | O4: 1219
B5: LP0047 | C5: G0011030001489E | D5: SGCC-ZSBX-Z08 : 0.5*300.5*625.8 CHR-FREE | E5: =LEFT(G5,4) -> SGCC | F5: =RIGHT(G5,3) -> Z08 | G5: SGCC-ZSBX-Z08 | H5: 0.5 | I5: 300.5 | J5: 625.8 | K5: =IF(J5="Coil",1,7.85*H5*I5*J5/10^6) -> 0.73810763 | L5: =IF(J5="Coil","KG,","Pcs") -> Pcs | M5: THRIVE PRECISION INDUSTRY CO.,LTD. | O5: 1219
B6: LP0047 | C6: G0011030001499ETD | D6: SGCC-ZSBX-Z08 : 0.5*290*640 CHR-FREE | E6: =LEFT(G6,4) -> SGCC | F6: =RIGHT(G6,3) -> Z18 | G6: SGCC-ZSBX-Z18 | H6: 0.5 | I6: 290 | J6: 640 | K6: =IF(J6="Coil",1,7.85*H6*I6*J6/10^6) -> 0.72848 | L6: =IF(J6="Coil","KG,","Pcs") -> Pcs | M6: 0 | O6: 1219
B7: LP0047 | C7: G0011030001529E | D7: SGCC-ZSBX-Z08 : 1.0*85*185 CHR-FREE | E7: =LEFT(G7,4) -> SGCC | F7: =RIGHT(G7,3) -> Z08 | G7: SGCC-ZSBX-Z08 | H7: 1 | I7: 85 | J7: 185 | K7: =IF(J7="Coil",1,7.85*H7*I7*J7/10^6) -> 0.12344125 | L7: =IF(J7="Coil","KG,","Pcs") -> Pcs | M7: UNIPART CO.,LTD. | O7: 1219
B8: LP0047 | C8: G0011030001529ETD | D8: SGCC-ZSBX-Z08 : 1.0*85*185 CHR-FREE | E8: =LEFT(G8,4) -> SGCC | F8: =RIGHT(G8,3) -> Z08 | G8: SGCC-ZSBX-Z08 | H8: 1 | I8: 85 | J8: 185 | K8: =IF(J8="Coil",1,7.85*H8*I8*J8/10^6) -> 0.12344125 | L8: =IF(J8="Coil","KG,","Pcs") -> Pcs | M8: UNIPART CO.,LTD. | O8: 1219
B9: LP0047 | C9: G0011030001533ETD | D9: SGCC-ZSBX-Z08 : 0.5*220*270 CHR-FREE | E9: =LEFT(G9,4) -> SGCC | F9: =RIGHT(G9,3) -> Z08 | G9: SGCC-ZSBX-Z08 | H9: 0.5 | I9: 220 | J9: 270 | K9: =IF(J9="Coil",1,7.85*H9*I9*J9/10^6) -> 0.233145 | L9: =IF(J9="Coil","KG,","Pcs") -> Pcs | M9: 0 | O9: 1219
B10: LP0047 | C10: G0011030001541E | D10: SGCC-ZS-EA-FB-Z08 : 0.8*166.8*573.7 CHR- | E10: =LEFT(G10,4) -> SGCC | F10: =RIGHT(G10,3) -> Z08 | G10: SGCC-ZS-EA-FB-Z08 | H10: 0.8 | I10: 166.8 | J10: 573.7 | K10: =IF(J10="Coil",1,7.85*H10*I10*J10/10^6) -> 0.60095304 | L10: =IF(J10="Coil","KG,","Pcs") -> Pcs | M10: 0 | O10: 1219
B11: LP0047 | C11: G0011030001541ETD | D11: SGCC-ZS-EA-FB-Z08 : 0.8*166.8*573.7 CHR- | E11: =LEFT(G11,4) -> SGCC | F11: =RIGHT(G11,3) -> Z08 | G11: SGCC-ZS-EA-FB-Z08 | H11: 0.8 | I11: 166.8 | J11: 573.7 | K11: =IF(J11="Coil",1,7.85*H11*I11*J11/10^6) -> 0.60095304 | L11: =IF(J11="Coil","KG,","Pcs") -> Pcs | M11: 0 | O11: 1219
B12: LP0047 | C12: G0011030001554E | D12: SGCC-ZSBX-Z08 : 0.5*235*525.5 CHR-FREE | E12: =LEFT(G12,4) -> SGCC | F12: =RIGHT(G12,3) -> Z08 | G12: SGCC-ZSBX-Z08 | H12: 0.5 | I12: 235 | J12: 525.5 | K12: =IF(J12="Coil",1,7.85*H12*I12*J12/10^6) -> 0.48470806 | L12: =IF(J12="Coil","KG,","Pcs") -> Pcs | M12: 0 | O12: 1219
B13: LP0047 | C13: G0011030001556E | D13: SGCC-ZSBX-Z08 :1.0*230*1220 CHR-FREE | E13: =LEFT(G13,4) -> SGCC | F13: =RIGHT(G13,3) -> Z08 | G13: SGCC-ZSBX-Z08 | H13: 1 | I13: 230 | J13: 1220 | K13: =IF(J13="Coil",1,7.85*H13*I13*J13/10^6) -> 2.20271 | L13: =IF(J13="Coil","KG,","Pcs") -> Pcs | M13: THRIVE PRECISION INDUSTRY CO.,LTD. | O13: 1219
B14: LP0047 | C14: G0011030001559E | D14: SGCC-ZSBX-Z08 : 1.0*189.4*546 CHR-FREE | E14: =LEFT(G14,4) -> SGCC | F14: =RIGHT(G14,3) -> Z08 | G14: SGCC-ZSBX-Z08 | H14: 1 | I14: 189.4 | J14: 546 | K14: =IF(J14="Coil",1,7.85*H14*I14*J14/10^6) -> 0.81178734 | L14: =IF(J14="Coil","KG,","Pcs") -> Pcs | M14: 0 | O14: 1219
B15: LP0047 | C15: G0011030001559ETD | D15: SGCC-ZSBX-Z08 : 1.0*189.4*546 CHR-FREE | E15: =LEFT(G15,4) -> SGCC | F15: =RIGHT(G15,3) -> Z08 | G15: SGCC-ZSBX-Z08 | H15: 1 | I15: 189.4 | J15: 546 | K15: =IF(J15="Coil",1,7.85*H15*I15*J15/10^6) -> 0.81178734 | L15: =IF(J15="Coil","KG,","Pcs") -> Pcs | M15: 0 | O15: 1219
B16: LP0047 | C16: G0011030001561ETD | D16: SGCC-ZSBX-Z08 : 0.5*80*550 CHR-FREE | E16: =LEFT(G16,4) -> SGCC | F16: =RIGHT(G16,3) -> Z08 | G16: SGCC-ZSBX-Z08 | H16: 0.5 | I16: 80 | J16: 550 | K16: =IF(J16="Coil",1,7.85*H16*I16*J16/10^6) -> 0.1727 | L16: =IF(J16="Coil","KG,","Pcs") -> Pcs | M16: UNIPART CO.,LTD. | O16: 1219
B17: LP0047 | C17: G0011030001562E | D17: SGCC-ZSBX-Z08 : 0.5*47*510 CHR-FREE | E17: =LEFT(G17,4) -> SGCC | F17: =RIGHT(G17,3) -> Z08 | G17: SGCC-ZSBX-Z08 | H17: 0.5 | I17: 47 | J17: 510 | K17: =IF(J17="Coil",1,7.85*H17*I17*J17/10^6) -> 0.09408225 | L17: =IF(J17="Coil","KG,","Pcs") -> Pcs | M17: UNIPART CO.,LTD. | O17: 1219
B18: LP0047 | C18: G0011030001562ETD | D18: SGCC-ZSBX-Z08 : 0.5*47*510 CHR-FREE | E18: =LEFT(G18,4) -> SGCC | F18: =RIGHT(G18,3) -> Z08 | G18: SGCC-ZSBX-Z08 | H18: 0.5 | I18: 47 | J18: 510 | K18: =IF(J18="Coil",1,7.85*H18*I18*J18/10^6) -> 0.09408225 | L18: =IF(J18="Coil","KG,","Pcs") -> Pcs | M18: UNIPART CO.,LTD. | O18: 1219
B19: LP0047 | C19: G0011030001563E | D19: SGCC-ZSBX-Z08 : 0.5*125*200 CHR-FREE | E19: =LEFT(G19,4) -> SGCC | F19: =RIGHT(G19,3) -> Z08 | G19: SGCC-ZSBX-Z08 | H19: 0.5 | I19: 125 | J19: 200 | K19: =IF(J19="Coil",1,7.85*H19*I19*J19/10^6) -> 0.098125 | L19: =IF(J19="Coil","KG,","Pcs") -> Pcs | M19: THRIVE PRECISION INDUSTRY CO.,LTD. | O19: 1219
B20: LP0047 | C20: G0011030001563ETD | D20: SGCC-ZSBX-Z08 : 0.5*125*200 CHR-FREE | E20: =LEFT(G20,4) -> SGCC | F20: =RIGHT(G20,3) -> Z08 | G20: SGCC-ZSBX-Z08 | H20: 0.5 | I20: 125 | J20: 200 | K20: =IF(J20="Coil",1,7.85*H20*I20*J20/10^6) -> 0.098125 | L20: =IF(J20="Coil","KG,","Pcs") -> Pcs | M20: THRIVE PRECISION INDUSTRY CO.,LTD. | O20: 1219
B21: LP0047 | C21: G0011030001568E | D21: SGCC-ZSBX-Z08 : 1.0*84*910 CHR-FREE | E21: =LEFT(G21,4) -> SGCC | F21: =RIGHT(G21,3) -> Z08 | G21: SGCC-ZSBX-Z08 | H21: 1 | I21: 84 | J21: 910 | K21: =IF(J21="Coil",1,7.85*H21*I21*J21/10^6) -> 0.600054 | L21: =IF(J21="Coil","KG,","Pcs") -> Pcs | M21: UNIPART CO.,LTD. | O21: 1219
B22: LP0047 | C22: G0011030001570E | D22: SGCC-ZSBX-Z08 : 0.5*58*496 CHR-FREE | E22: =LEFT(G22,4) -> SGCC | F22: =RIGHT(G22,3) -> Z08 | G22: SGCC-ZSBX-Z08 | H22: 0.5 | I22: 58 | J22: 496 | K22: =IF(J22="Coil",1,7.85*H22*I22*J22/10^6) -> 0.1129144 | L22: =IF(J22="Coil","KG,","Pcs") -> Pcs | M22: 0 | O22: 1219
B23: LP0047 | C23: G0011030001572E | D23: SGCC-ZSBX-Z08 : 0.5*157*419 CHR-FREE | E23: =LEFT(G23,4) -> SGCC | F23: =RIGHT(G23,3) -> Z08 | G23: SGCC-ZSBX-Z08 | H23: 0.5 | I23: 157 | J23: 419 | K23: =IF(J23="Coil",1,7.85*H23*I23*J23/10^6) -> 0.25819828 | L23: =IF(J23="Coil","KG,","Pcs") -> Pcs | M23: UNIPART CO.,LTD. | O23: 1219
B24: LP0047 | C24: G0011030001572ETD | D24: SGCC-ZSBX-Z08 : 0.5*157*419 CHR-FREE | E24: =LEFT(G24,4) -> SGCC | F24: =RIGHT(G24,3) -> Z08 | G24: SGCC-ZSBX-Z08 | H24: 0.5 | I24: 157 | J24: 419 | K24: =IF(J24="Coil",1,7.85*H24*I24*J24/10^6) -> 0.25819828 | L24: =IF(J24="Coil","KG,","Pcs") -> Pcs | M24: UNIPART CO.,LTD. | O24: 1219
B25: LP0047 | C25: G0011030001573ETD | D25: SGCC-ZSBX-Z08 : 0.6*144*184 CHR-FREE | E25: =LEFT(G25,4) -> SGCC | F25: =RIGHT(G25,3) -> Z08 | G25: SGCC-ZSBX-Z08 | H25: 0.6 | I25: 144 | J25: 184 | K25: =IF(J25="Coil",1,7.85*H25*I25*J25/10^6) -> 0.12479616 | L25: =IF(J25="Coil","KG,","Pcs") -> Pcs | M25: UNIPART CO.,LTD. | O25: 1219
B26: LP0047 | C26: G0011030001577E | D26: SGCC-ZSBX-Z08 : 1.0*134*493 CHR-FREE | E26: =LEFT(G26,4) -> SGCC | F26: =RIGHT(G26,3) -> Z08 | G26: SGCC-ZSBX-Z08 | H26: 1 | I26: 134 | J26: 493 | K26: =IF(J26="Coil",1,7.85*H26*I26*J26/10^6) -> 0.5185867 | L26: =IF(J26="Coil","KG,","Pcs") -> Pcs | M26: UNIPART CO.,LTD. | O26: 1219
B27: LP0047 | C27: G0011030001578E | D27: SGCC-ZSBX-Z08 : 1.0*217*217 CHR-FREE | E27: =LEFT(G27,4) -> SGCC | F27: =RIGHT(G27,3) -> Z08 | G27: SGCC-ZSBX-Z08 | H27: 1 | I27: 217 | J27: 217 | K27: =IF(J27="Coil",1,7.85*H27*I27*J27/10^6) -> 0.36964865 | L27: =IF(J27="Coil","KG,","Pcs") -> Pcs | M27: UNIPART CO.,LTD. | O27: 1219
B28: LP0047 | C28: G0011030001597E | D28: SGCC-ZSBX-Z08 : 1.0*200*200 CHR-FREE | E28: =LEFT(G28,4) -> SGCC | F28: =RIGHT(G28,3) -> Z08 | G28: SGCC-ZSBX-Z08 | H28: 1 | I28: 200 | J28: 200 | K28: =IF(J28="Coil",1,7.85*H28*I28*J28/10^6) -> 0.314 | L28: =IF(J28="Coil","KG,","Pcs") -> Pcs | M28: UNIPART CO.,LTD. | O28: 1219
B29: LP0047 | C29: G0011030001600E | D29: SGCC-ZSBX-Z08 : 1.0*58*700 CHR-FREE | E29: =LEFT(G29,4) -> SGCC | F29: =RIGHT(G29,3) -> Z08 | G29: SGCC-ZSBX-Z08 | H29: 1 | I29: 58 | J29: 700 | K29: =IF(J29="Coil",1,7.85*H29*I29*J29/10^6) -> 0.31871 | L29: =IF(J29="Coil","KG,","Pcs") -> Pcs | M29: UNIPART CO.,LTD. | O29: 1219
B30: LP0047 | C30: G0011030001601E | D30: SGCC-ZSBX-Z08 : 0.6*55*335 CHR-FREE | E30: =LEFT(G30,4) -> SGCC | F30: =RIGHT(G30,3) -> Z08 | G30: SGCC-ZSBX-Z08 | H30: 0.6 | I30: 55 | J30: 335 | K30: =IF(J30="Coil",1,7.85*H30*I30*J30/10^6) -> 0.08678175 | L30: =IF(J30="Coil","KG,","Pcs") -> Pcs | M30: THRIVE PRECISION INDUSTRY CO.,LTD. | O30: 1219
B31: LP0047 | C31: G0011030001634E | D31: SGCC-ZSBX-Z08 : 0.6*156*1220 CHR-FREE | E31: =LEFT(G31,4) -> SGCC | F31: =RIGHT(G31,3) -> Z08 | G31: SGCC-ZSBX-Z08 | H31: 0.6 | I31: 156 | J31: 1220 | K31: =IF(J31="Coil",1,7.85*H31*I31*J31/10^6) -> 0.8964072 | L31: =IF(J31="Coil","KG,","Pcs") -> Pcs | M31: THRIVE PRECISION INDUSTRY CO.,LTD. | O31: 1219
B32: LP0047 | C32: G0011030001644E | D32: SGCC-ZSBX-Z08 : 0.8*451*563 CHR-FREE | E32: =LEFT(G32,4) -> SGCC | F32: =RIGHT(G32,3) -> Z08 | G32: SGCC-ZSBX-Z08 | H32: 0.8 | I32: 451 | J32: 563 | K32: =IF(J32="Coil",1,7.85*H32*I32*J32/10^6) -> 1.5945736 | L32: =IF(J32="Coil","KG,","Pcs") -> Pcs | M32: 0 | O32: 1219
B33: LP0047 | C33: G0011030001644ETD | D33: SGCC-ZSBX-Z08 : 0.8*451*563 CHR-FREE | E33: =LEFT(G33,4) -> SGCC | F33: =RIGHT(G33,3) -> Z08 | G33: SGCC-ZSBX-Z08 | H33: 0.8 | I33: 451 | J33: 563 | K33: =IF(J33="Coil",1,7.85*H33*I33*J33/10^6) -> 1.5945736 | L33: =IF(J33="Coil","KG,","Pcs") -> Pcs | M33: 0 | O33: 1219
B34: LP0047 | C34: G0011030001645E | D34: SGCC-ZSBX-Z08 : 0.5*299*325 CHR-FREE | E34: =LEFT(G34,4) -> SGCC | F34: =RIGHT(G34,3) -> Z08 | G34: SGCC-ZSBX-Z08 | H34: 0.5 | I34: 299 | J34: 325 | K34: =IF(J34="Coil",1,7.85*H34*I34*J34/10^6) -> 0.38141188 | L34: =IF(J34="Coil","KG,","Pcs") -> Pcs | M34: 0 | O34: 1219
B35: LP0047 | C35: G0011030001645ETD | D35: SGCC-ZSBX-Z08 : 0.5*299*325 CHR-FREE | E35: =LEFT(G35,4) -> SGCC | F35: =RIGHT(G35,3) -> Z08 | G35: SGCC-ZSBX-Z08 | H35: 0.5 | I35: 299 | J35: 325 | K35: =IF(J35="Coil",1,7.85*H35*I35*J35/10^6) -> 0.38141188 | L35: =IF(J35="Coil","KG,","Pcs") -> Pcs | M35: 0 | O35: 1219
B36: LP0047 | C36: G0011030001649ETD | D36: SGCC-ZSBX-Z08 : 0.6*350*800 CHR-FREE | E36: =LEFT(G36,4) -> SGCC | F36: =RIGHT(G36,3) -> Z08 | G36: SGCC-ZSBX-Z08 | H36: 0.6 | I36: 350 | J36: 800 | K36: =IF(J36="Coil",1,7.85*H36*I36*J36/10^6) -> 1.3188 | L36: =IF(J36="Coil","KG,","Pcs") -> Pcs | M36: 0 | O36: 1219
B37: LP0047 | C37: G0011030001650E | D37: SGCC-ZSBX-Z08 : 0.5*235*300 CHR-FREE | E37: =LEFT(G37,4) -> SGCC | F37: =RIGHT(G37,3) -> Z08 | G37: SGCC-ZSBX-Z08 | H37: 0.5 | I37: 235 | J37: 300 | K37: =IF(J37="Coil",1,7.85*H37*I37*J37/10^6) -> 0.2767125 | L37: =IF(J37="Coil","KG,","Pcs") -> Pcs | M37: 0 | O37: 1219
B38: LP0047 | C38: G0011030001661E | D38: SGCC-ZSBX-Z08 : 0.6*290*340 CHR-FREE | E38: =LEFT(G38,4) -> SGCC | F38: =RIGHT(G38,3) -> Z08 | G38: SGCC-ZSBX-Z08 | H38: 0.6 | I38: 290 | J38: 340 | K38: =IF(J38="Coil",1,7.85*H38*I38*J38/10^6) -> 0.464406 | L38: =IF(J38="Coil","KG,","Pcs") -> Pcs | M38: CHUN SIANG AUTOPART CO.,LTD. | O38: 1219
B39: LP0047 | C39: G0011030001661ETD | D39: SGCC-ZSBX-Z08 : 0.6*290*340 CHR-FREE | E39: =LEFT(G39,4) -> SGCC | F39: =RIGHT(G39,3) -> Z08 | G39: SGCC-ZSBX-Z08 | H39: 0.6 | I39: 290 | J39: 340 | K39: =IF(J39="Coil",1,7.85*H39*I39*J39/10^6) -> 0.464406 | L39: =IF(J39="Coil","KG,","Pcs") -> Pcs | M39: CHUN SIANG AUTOPART CO.,LTD. | O39: 1219
B40: LP0047 | C40: G0011030001662E | D40: SGCC-ZSBX-Z08 : 0.5*172*221 CHR-FREE | E40: =LEFT(G40,4) -> SGCC | F40: =RIGHT(G40,3) -> Z08 | G40: SGCC-ZSBX-Z08 | H40: 0.5 | I40: 172 | J40: 221 | K40: =IF(J40="Coil",1,7.85*H40*I40*J40/10^6) -> 0.1491971 | L40: =IF(J40="Coil","KG,","Pcs") -> Pcs | M40: 0 | O40: 1219
...

Sheet Summary
A1: Material order / Stock Balance / CTC Forecast latest review 22.05.2026
A2: PTT FORECAST FIXED WK20 received 15 May 2026 | P2: New PO shipment | R2: Urgent sourcing
A4: Item | B4: Customer | C4: Spec | D4: T | E4: W | F4: L | G4: 01-17 May 2026 | J4: 18-31 May 2026 | M4: Jun 2026 | P4: Jul 2026 | S4: Aug 2026 | V4: Sep 2026 | Y4: Oct 2026
G5: Material ETA | H5: Actual delivered | I5: Stock End | J5: Material ETA | K5: be delivery | L5: Stock End | M5: Material ETA | N5: Forecast | O5: Stock End | P5: Material ETA | Q5: =N5 -> Forecast | R5: Stock End | S5: Material ETA | T5: =Q5 -> Forecast | U5: Stock End | V5: Material ETA | W5: =T5 -> Forecast | X5: Stock End | Y5: Material ETA | Z5: =W5 -> Forecast | AA5: Stock End
A6: 1 | B6: CARRIER | C6: SGCC | D6: 0.5 | E6: 1219 | F6: Coil | G6: 20000 | H6: ='Sum of data'!G3 -> 9825.4803 | I6: ='Sum of data'!V45 -> 23820 | J6: 20000 | K6: ='Sum of data'!H3 -> 9475.3044 | L6: =I6+J6-K6 -> 34344.696 | N6: ='Sum of data'!I25 -> 11979.617 | O6: =L6+M6-N6 -> 22365.078 | Q6: ='Sum of data'!J25 -> 12081.368 | R6: =O6+P6-Q6 -> 10283.71 | S6: 40000 | T6: ='Sum of data'!K25 -> 13710.983 | U6: =R6+S6-T6 -> 36572.727 | W6: ='Sum of data'!L25 -> 17635.713 | X6: =U6+V6-W6 -> 18937.013 | Z6: ='Sum of data'!M25 -> 446.31789 | AA6: =X6+Y6-Z6 -> 18490.696
A7: =A6+1 -> 2 | B7: CARRIER | C7: SGCC | D7: 0.6 | E7: 1219 | F7: Coil | G7: 10000 | H7: ='Sum of data'!G4 -> 30858.665 | I7: ='Sum of data'!V46 -> 53117 | J7: 10000 | K7: ='Sum of data'!H4 -> 9157.9048 | L7: =I7+J7-K7 -> 53959.095 | M7: 64540 | N7: ='Sum of data'!I26 -> 24216.087 | O7: =L7+M7-N7 -> 94283.008 | Q7: ='Sum of data'!J26 -> 22345.812 | R7: =O7+P7-Q7 -> 71937.196 | S7: 20000 | T7: ='Sum of data'!K26 -> 22020.32 | U7: =R7+S7-T7 -> 69916.876 | W7: ='Sum of data'!L26 -> 45866.023 | X7: =U7+V7-W7 -> 24050.853 | Z7: ='Sum of data'!M26 -> 4974.2104 | AA7: =X7+Y7-Z7 -> 19076.643
A8: =A7+1 -> 3 | B8: CARRIER | C8: SGCD | D8: 0.6 | E8: 1219 | F8: Coil | H8: ='Sum of data'!G5 -> 2905.0489 | I8: ='Sum of data'!V47 -> 10002 | K8: ='Sum of data'!H5 -> 792.03266 | L8: =I8+J8-K8 -> 9209.9673 | N8: ='Sum of data'!I27 -> 3226.0641 | O8: =L8+M8-N8 -> 5983.9033 | P8: 25000 | Q8: ='Sum of data'!J27 -> 3687.0946 | R8: =O8+P8-Q8 -> 27296.809 | T8: ='Sum of data'!K27 -> 3756.6106 | U8: =R8+S8-T8 -> 23540.198 | W8: ='Sum of data'!L27 -> 7709.9234 | X8: =U8+V8-W8 -> 15830.275 | Z8: ='Sum of data'!M27 -> 0 | AA8: =X8+Y8-Z8 -> 15830.275
A9: =A8+1 -> 4 | B9: CARRIER | C9: SGCD | D9: 0.6 | E9: 915 | F9: Coil | H9: ='Sum of data'!G6 -> 8854.8471 | I9: ='Sum of data'!V48 -> 7450 | J9: 25000 | K9: ='Sum of data'!H6 -> 11746.693 | L9: =I9+J9-K9 -> 20703.307 | N9: ='Sum of data'!I28 -> 20612.527 | O9: =L9+M9-N9 -> 90.779612 | P9: 45000 | Q9: ='Sum of data'!J28 -> 16908.714 | R9: =O9+P9-Q9 -> 28182.066 | S9: 45000 | T9: ='Sum of data'!K28 -> 14171.113 | U9: =R9+S9-T9 -> 59010.953 | W9: ='Sum of data'!L28 -> 40902.984 | X9: =U9+V9-W9 -> 18107.969 | Z9: ='Sum of data'!M28 -> 0 | AA9: =X9+Y9-Z9 -> 18107.969
A10: =A9+1 -> 5 | B10: CARRIER | C10: SGCD | D10: 0.6 | E10: 1340 | F10: Coil | G10: 20000 | H10: ='Sum of data'!G7 -> 2082.8798 | I10: ='Sum of data'!V49 -> 162 | J10: 20000 | K10: ='Sum of data'!H7 -> 1458.0158 | L10: =I10+J10-K10 -> 18703.984 | N10: ='Sum of data'!I29 -> 3872.5942 | O10: =L10+M10-N10 -> 14831.39 | P10: 25000 | Q10: ='Sum of data'!J29 -> 3349.2706 | R10: =O10+P10-Q10 -> 36482.119 | T10: ='Sum of data'!K29 -> 6593.8766 | U10: =R10+S10-T10 -> 29888.243 | W10: ='Sum of data'!L29 -> 4196.482 | X10: =U10+V10-W10 -> 25691.761 | Z10: ='Sum of data'!M29 -> 0 | AA10: =X10+Y10-Z10 -> 25691.761
A11: =A10+1 -> 6 | B11: CARRIER | C11: SGCC | D11: 0.7 | E11: 1219 | F11: Coil | H11: ='Sum of data'!G8 -> 58782.913 | I11: ='Sum of data'!V50 -> 18764 | K11: ='Sum of data'!H8 -> 6029.5518 | L11: =I11+J11-K11 -> 12734.448 | M11: 50000 | N11: ='Sum of data'!I30 -> 46149.551 | O11: =L11+M11-N11 -> 16584.897 | P11: 70000 | Q11: ='Sum of data'!J30 -> 59802.289 | R11: =O11+P11-Q11 -> 26782.608 | S11: 50000 | T11: ='Sum of data'!K30 -> 28520.12 | U11: =R11+S11-T11 -> 48262.489 | V11: 50000 | W11: ='Sum of data'!L30 -> 76112.855 | X11: =U11+V11-W11 -> 22149.634 | Z11: ='Sum of data'!M30 -> 10731.365 | AA11: =X11+Y11-Z11 -> 11418.269
A12: =A11+1 -> 7 | B12: CARRIER | C12: SGCC | D12: 0.8 | E12: 1219 | F12: Coil | H12: ='Sum of data'!G9 -> 52505.913 | I12: ='Sum of data'!V51 -> 70660 | K12: ='Sum of data'!H9 -> 13105.103 | L12: =I12+J12-K12 -> 57554.897 | N12: ='Sum of data'!I31 -> 45104.969 | O12: =L12+M12-N12 -> 12449.928 | P12: 80000 | Q12: ='Sum of data'!J31 -> 44257.407 | R12: =O12+P12-Q12 -> 48192.521 | S12: 40000 | T12: ='Sum of data'!K31 -> 46142.297 | U12: =R12+S12-T12 -> 42050.224 | V12: 60000 | W12: ='Sum of data'!L31 -> 82059.969 | X12: =U12+V12-W12 -> 19990.255 | Z12: ='Sum of data'!M31 -> 6391.1899 | AA12: =X12+Y12-Z12 -> 13599.065
A13: =A12+1 -> 8 | B13: CARRIER | C13: SGCD | D13: 0.8 | E13: 1219 | F13: Coil | H13: ='Sum of data'!G10 -> 76.8672 | I13: ='Sum of data'!V52 -> 15105 | K13: ='Sum of data'!H10 -> 169.10784 | L13: =I13+J13-K13 -> 14935.892 | N13: ='Sum of data'!I32 -> 287.76005 | O13: =L13+M13-N13 -> 14648.132 | Q13: ='Sum of data'!J32 -> 241.02479 | R13: =O13+P13-Q13 -> 14407.107 | T13: ='Sum of data'!K32 -> 482.04958 | U13: =R13+S13-T13 -> 13925.058 | W13: ='Sum of data'!L32 -> 321.36639 | X13: =U13+V13-W13 -> 13603.691 | Z13: ='Sum of data'!M32 -> 0 | AA13: =X13+Y13-Z13 -> 13603.691
A14: =A13+1 -> 9 | B14: CARRIER | C14: SGCD | D14: 0.8 | E14: 935 | F14: Z22 | H14: ='Sum of data'!G11 -> 15181.536 | I14: ='Sum of data'!V53 -> 30264 | K14: ='Sum of data'!H11 -> 1481.1254 | L14: =I14+J14-K14 -> 28782.875 | M14: 25000 | N14: ='Sum of data'!I33 -> 29622.509 | O14: =L14+M14-N14 -> 24160.366 | P14: 30000 | Q14: ='Sum of data'!J33 -> 16662.661 | R14: =O14+P14-Q14 -> 37497.705 | S14: 30000 | T14: ='Sum of data'!K33 -> 14811.254 | U14: =R14+S14-T14 -> 52686.45 | V14: 30000 | W14: ='Sum of data'!L33 -> 18514.068 | X14: =U14+V14-W14 -> 64172.382 | Z14: ='Sum of data'!M33 -> 20365.475 | AA14: =X14+Y14-Z14 -> 43806.907
A15: =A14+1 -> 10 | B15: CARRIER | C15: SGCC | D15: 1 | E15: 1219 | F15: Coil | H15: ='Sum of data'!G12 -> 13372.246 | I15: ='Sum of data'!V54 -> 7605 | J15: 8000 | K15: ='Sum of data'!H12 -> 5001.2667 | L15: =I15+J15-K15 -> 10603.733 | M15: 25000 | N15: ='Sum of data'!I34 -> 9402.5236 | O15: =L15+M15-N15 -> 26201.21 | P15: 20000 | Q15: ='Sum of data'!J34 -> 13227.861 | R15: =O15+P15-Q15 -> 32973.349 | T15: ='Sum of data'!K34 -> 8835.7995 | U15: =R15+S15-T15 -> 24137.549 | V15: 20000 | W15: ='Sum of data'!L34 -> 18180.306 | X15: =U15+V15-W15 -> 25957.243 | Z15: ='Sum of data'!M34 -> 3407.3931 | AA15: =X15+Y15-Z15 -> 22549.85
A16: =A15+1 -> 11 | B16: CARRIER | C16: SGCC | D16: 1.2 | E16: 1219 | F16: Coil | H16: ='Sum of data'!G13 -> 34179.79 | I16: ='Sum of data'!V55 -> 52874 | K16: ='Sum of data'!H13 -> 11036.362 | L16: =I16+J16-K16 -> 41837.638 | M16: 50000 | N16: ='Sum of data'!I35 -> 39446.357 | O16: =L16+M16-N16 -> 52391.281 | P16: 40000 | Q16: ='Sum of data'!J35 -> 30521.695 | R16: =O16+P16-Q16 -> 61869.586 | T16: ='Sum of data'!K35 -> 23984.152 | U16: =R16+S16-T16 -> 37885.433 | V16: 40000 | W16: ='Sum of data'!L35 -> 43353.674 | X16: =U16+V16-W16 -> 34531.76 | Z16: ='Sum of data'!M35 -> 22675.465 | AA16: =X16+Y16-Z16 -> 11856.295
A17: =A16+1 -> 12 | B17: CARRIER | C17: SGCC | D17: 1.6 | E17: 1219 | F17: Z18 | H17: ='Sum of data'!G14 -> 9986.6778 | I17: ='Sum of data'!V56 -> 7682 | J17: 8000 | K17: ='Sum of data'!H14 -> 13269.409 | L17: =I17+J17-K17 -> 2412.5912 | M17: 20000 | N17: ='Sum of data'!I36 -> 22496.04 | O17: =L17+M17-N17 -> -83.448991 | P17: 40000 | Q17: ='Sum of data'!J36 -> 20423.827 | R17: =O17+P17-Q17 -> 19492.724 | S17: 60000 | T17: ='Sum of data'!K36 -> 17388.183 | U17: =R17+S17-T17 -> 62104.541 | V17: 20000 | W17: ='Sum of data'!L36 -> 48781.652 | X17: =U17+V17-W17 -> 33322.889 | Z17: ='Sum of data'!M36 -> 0 | AA17: =X17+Y17-Z17 -> 33322.889
A18: =A17+1 -> 13 | B18: CARRIER | C18: SGCC | D18: 2 | E18: 1219 | F18: Z08 | H18: ='Sum of data'!G15 -> 35.64528 | I18: ='Sum of data'!V57 -> 0 | K18: ='Sum of data'!H15 -> 1282.668 | L18: =I18+J18-K18 -> -1282.668 | N18: ='Sum of data'!I37 -> 1530.4936 | O18: =L18+M18-N18 -> -2813.1616 | Q18: ='Sum of data'!J37 -> 831.19384 | R18: =O18+P18-Q18 -> -3644.3554 | T18: ='Sum of data'!K37 -> 836.03301 | U18: =R18+S18-T18 -> -4480.3884 | W18: ='Sum of data'!L37 -> 2390.3858 | X18: =U18+V18-W18 -> -6870.7743 | Z18: ='Sum of data'!M37 -> 0 | AA18: =X18+Y18-Z18 -> -6870.7743
A19: =A18+1 -> 14 | B19: CARRIER | C19: SGCC | D19: 2 | E19: 1219 | F19: Z18 | H19: ='Sum of data'!G16 -> 20160.562 | I19: ='Sum of data'!V58 -> 79028 | K19: ='Sum of data'!H16 -> 18251.591 | L19: =I19+J19-K19 -> 60776.409 | M19: 50000 | N19: ='Sum of data'!I38 -> 36538.477 | O19: =L19+M19-N19 -> 74237.932 | P19: =25000+20000 -> 45000 | Q19: ='Sum of data'!J38 -> 45234.339 | R19: =O19+P19-Q19 -> 74003.593 | S19: 40000 | T19: ='Sum of data'!K38 -> 30909.72 | U19: =R19+S19-T19 -> 83093.873 | V19: 60000 | W19: ='Sum of data'!L38 -> 56761.017 | X19: =U19+V19-W19 -> 86332.856 | Z19: ='Sum of data'!M38 -> 3892.9159 | AA19: =X19+Y19-Z19 -> 82439.94
A20: =A19+1 -> 15 | B20: CARRIER | C20: SGCC | D20: 2 | E20: 1219 | F20: Z22 | H20: ='Sum of data'!G17 -> 19060.678 | I20: ='Sum of data'!V59 -> 3855 | K20: ='Sum of data'!H17 -> 17523.553 | L20: =I20+J20-K20 -> -13668.553 | M20: 30000 | N20: ='Sum of data'!I39 -> 17918.196 | O20: =L20+M20-N20 -> -1586.7489 | P20: 50000 | Q20: ='Sum of data'!J39 -> 15728.35 | R20: =O20+P20-Q20 -> 32684.901 | S20: 40000 | T20: ='Sum of data'!K39 -> 15664.061 | U20: =R20+S20-T20 -> 57020.841 | V20: 20000 | W20: ='Sum of data'!L39 -> 36943.974 | X20: =U20+V20-W20 -> 40076.867 | Z20: ='Sum of data'!M39 -> 387.67775 | AA20: =X20+Y20-Z20 -> 39689.189
A21: Summary | G21: =SUM(G6:G20) -> 50000 | H21: =SUM(H6:H20) -> 277869.75 | I21: =SUM(I6:I20) -> 380388 | J21: =SUM(J6:J20) -> 91000 | K21: =SUM(K6:K20) -> 119779.69 | L21: =SUM(L6:L20) -> 351608.31 | M21: =SUM(M6:M20) -> 314540 | N21: =SUM(N6:N20) -> 312403.77 | ... AA21: =SUM(AA6:AA20) -> 362612.66

Sheet Sum of data
B1: 1] Sum of Balance this month (Apr'2025) - SO003 11.04.2026
B2: Spec | C2: T | D2: W | E2: L/Coating | F2: PO Kgs | G2: Delivered (kg) | H2: PO Bal (kg) | I2: latest PO receive 15.05.2026
B3: SGCC | C3: 0.5 | D3: 1219 | E3: Coil | F3: =SUMIFS('SO003'!AI:AI,'SO003'!$AA:$AA,'Sum of data'!$B3,'SO003'!$AE:$AE,'Sum of data'!$C3,'SO003'!$AC:$AC,'Sum of data'!$D3,'SO003'!$AL:$AL,5) -> 19300.785 | G3: =SUMIFS('SO003'!AJ:AJ,'SO003'!$AA:$AA,'Sum of data'!$B3,'SO003'!$AE:$AE,'Sum of data'!$C3,'SO003'!$AC:$AC,'Sum of data'!$D3,'SO003'!$AL:$AL,5) -> 9825.4803 | H3: =SUMIFS('SO003'!AK:AK,'SO003'!$AA:$AA,'Sum of data'!$B3,'SO003'!$AE:$AE,'Sum of data'!$C3,'SO003'!$AC:$AC,'Sum of data'!$D3,'SO003'!$AL:$AL,5) -> 9475.3044
B4: SGCC | C4: 0.6 | D4: 1219 | E4: Coil | F4: =SUMIFS('SO003'!AI:AI,'SO003'!$AA:$AA,'Sum of data'!$B4,'SO003'!$AE:$AE,'Sum of data'!$C4,'SO003'!$AC:$AC,'Sum of data'!$D4,'SO003'!$AL:$AL,5) -> 40016.57 | G4: =SUMIFS('SO003'!AJ:AJ,'SO003'!$AA:$AA,'Sum of data'!$B4,'SO003'!$AE:$AE,'Sum of data'!$C4,'SO003'!$AC:$AC,'Sum of data'!$D4,'SO003'!$AL:$AL,5) -> 30858.665 | H4: =SUMIFS('SO003'!AK:AK,'SO003'!$AA:$AA,'Sum of data'!$B4,'SO003'!$AE:$AE,'Sum of data'!$C4,'SO003'!$AC:$AC,'Sum of data'!$D4,'SO003'!$AL:$AL,5) -> 9157.9048
B5: SGCD | C5: 0.6 | D5: 1219 | E5: Coil | F5: =SUMIFS('SO003'!AI:AI,'SO003'!$AA:$AA,'Sum of data'!$B5,'SO003'!$AE:$AE,'Sum of data'!$C5,'SO003'!$AC:$AC,'Sum of data'!$D5,'SO003'!$AL:$AL,5) -> 3697.0815 | G5: =SUMIFS('SO003'!AJ:AJ,'SO003'!$AA:$AA,'Sum of data'!$B5,'SO003'!$AE:$AE,'Sum of data'!$C5,'SO003'!$AC:$AC,'Sum of data'!$D5,'SO003'!$AL:$AL,5) -> 2905.0489 | H5: =SUMIFS('SO003'!AK:AK,'SO003'!$AA:$AA,'Sum of data'!$B5,'SO003'!$AE:$AE,'Sum of data'!$C5,'SO003'!$AC:$AC,'Sum of data'!$D5,'SO003'!$AL:$AL,5) -> 792.03266
B6: SGCD | C6: 0.6 | D6: 915 | E6: Coil | F6: =SUMIFS('SO003'!AI:AI,'SO003'!$AA:$AA,'Sum of data'!$B6,'SO003'!$AE:$AE,'Sum of data'!$C6,'SO003'!$AC:$AC,'Sum of data'!$D6,'SO003'!$AL:$AL,5) -> 20601.54 | G6: =SUMIFS('SO003'!AJ:AJ,'SO003'!$AA:$AA,'Sum of data'!$B6,'SO003'!$AE:$AE,'Sum of data'!$C6,'SO003'!$AC:$AC,'Sum of data'!$D6,'SO003'!$AL:$AL,5) -> 8854.8471 | H6: =SUMIFS('SO003'!AK:AK,'SO003'!$AA:$AA,'Sum of data'!$B6,'SO003'!$AE:$AE,'Sum of data'!$C6,'SO003'!$AC:$AC,'Sum of data'!$D6,'SO003'!$AL:$AL,5) -> 11746.693
B7: SGCD | C7: 0.6 | D7: 1340 | E7: Coil | F7: =SUMIFS('SO003'!AI:AI,'SO003'!$AA:$AA,'Sum of data'!$B7,'SO003'!$AE:$AE,'Sum of data'!$C7,'SO003'!$AC:$AC,'Sum of data'!$D7,'SO003'!$AL:$AL,5) -> 3540.8956 | G7: =SUMIFS('SO003'!AJ:AJ,'SO003'!$AA:$AA,'Sum of data'!$B7,'SO003'!$AE:$AE,'Sum of data'!$C7,'SO003'!$AC:$AC,'Sum of data'!$D7,'SO003'!$AL:$AL,5) -> 2082.8798 | H7: =SUMIFS('SO003'!AK:AK,'SO003'!$AA:$AA,'Sum of data'!$B7,'SO003'!$AE:$AE,'Sum of data'!$C7,'SO003'!$AC:$AC,'Sum of data'!$D7,'SO003'!$AL:$AL,5) -> 1458.0158
B8: SGCC | C8: 0.7 | D8: 1219 | E8: Coil | F8: =SUMIFS('SO003'!AI:AI,'SO003'!$AA:$AA,'Sum of data'!$B8,'SO003'!$AE:$AE,'Sum of data'!$C8,'SO003'!$AC:$AC,'Sum of data'!$D8,'SO003'!$AL:$AL,5) -> 64812.464 | G8: =SUMIFS('SO003'!AJ:AJ,'SO003'!$AA:$AA,'Sum of data'!$B8,'SO003'!$AE:$AE,'Sum of data'!$C8,'SO003'!$AC:$AC,'Sum of data'!$D8,'SO003'!$AL:$AL,5) -> 58782.913 | H8: =SUMIFS('SO003'!AK:AK,'SO003'!$AA:$AA,'Sum of data'!$B8,'SO003'!$AE:$AE,'Sum of data'!$C8,'SO003'!$AC:$AC,'Sum of data'!$D8,'SO003'!$AL:$AL,5) -> 6029.5518
B9: SGCC | C9: 0.8 | D9: 1219 | E9: Coil | F9: =SUMIFS('SO003'!AI:AI,'SO003'!$AA:$AA,'Sum of data'!$B9,'SO003'!$AE:$AE,'Sum of data'!$C9,'SO003'!$AC:$AC,'Sum of data'!$D9,'SO003'!$AL:$AL,5) -> 65611.016 | G9: =SUMIFS('SO003'!AJ:AJ,'SO003'!$AA:$AA,'Sum of data'!$B9,'SO003'!$AE:$AE,'Sum of data'!$C9,'SO003'!$AC:$AC,'Sum of data'!$D9,'SO003'!$AL:$AL,5) -> 52505.913 | H9: =SUMIFS('SO003'!AK:AK,'SO003'!$AA:$AA,'Sum of data'!$B9,'SO003'!$AE:$AE,'Sum of data'!$C9,'SO003'!$AC:$AC,'Sum of data'!$D9,'SO003'!$AL:$AL,5) -> 13105.103
B10: SGCD | C10: 0.8 | D10: 1219 | E10: Coil | F10: =SUMIFS('SO003'!AI:AI,'SO003'!$AA:$AA,'Sum of data'!$B10,'SO003'!$AE:$AE,'Sum of data'!$C10,'SO003'!$AC:$AC,'Sum of data'!$D10,'SO003'!$AL:$AL,5) -> 245.97504 | G10: =SUMIFS('SO003'!AJ:AJ,'SO003'!$AA:$AA,'Sum of data'!$B10,'SO003'!$AE:$AE,'Sum of data'!$C10,'SO003'!$AC:$AC,'Sum of data'!$D10,'SO003'!$AL:$AL,5) -> 76.8672 | H10: =SUMIFS('SO003'!AK:AK,'SO003'!$AA:$AA,'Sum of data'!$B10,'SO003'!$AE:$AE,'Sum of data'!$C10,'SO003'!$AC:$AC,'Sum of data'!$D10,'SO003'!$AL:$AL,5) -> 169.10784
B11: SGCD | C11: 0.8 | D11: 935 | E11: Z22 | F11: =SUMIFS('SO003'!AI:AI,'SO003'!$AA:$AA,'Sum of data'!$B11,'SO003'!$AE:$AE,'Sum of data'!$C11,'SO003'!$AC:$AC,'Sum of data'!$D11,'SO003'!$AL:$AL,5) -> 16662.661 | G11: =SUMIFS('SO003'!AJ:AJ,'SO003'!$AA:$AA,'Sum of data'!$B11,'SO003'!$AE:$AE,'Sum of data'!$C11,'SO003'!$AC:$AC,'Sum of data'!$D11,'SO003'!$AL:$AL,5) -> 15181.536 | H11: =SUMIFS('SO003'!AK:AK,'SO003'!$AA:$AA,'Sum of data'!$B11,'SO003'!$AE:$AE,'Sum of data'!$C11,'SO003'!$AC:$AC,'Sum of data'!$D11,'SO003'!$AL:$AL,5) -> 1481.1254
B12: SGCC | C12: 1 | D12: 1219 | E12: Coil | F12: =SUMIFS('SO003'!AI:AI,'SO003'!$AA:$AA,'Sum of data'!$B12,'SO003'!$AE:$AE,'Sum of data'!$C12,'SO003'!$AC:$AC,'Sum of data'!$D12,'SO003'!$AL:$AL,5) -> 18373.513 | G12: =SUMIFS('SO003'!AJ:AJ,'SO003'!$AA:$AA,'Sum of data'!$B12,'SO003'!$AE:$AE,'Sum of data'!$C12,'SO003'!$AC:$AC,'Sum of data'!$D12,'SO003'!$AL:$AL,5) -> 13372.246 | H12: =SUMIFS('SO003'!AK:AK,'SO003'!$AA:$AA,'Sum of data'!$B12,'SO003'!$AE:$AE,'Sum of data'!$C12,'SO003'!$AC:$AC,'Sum of data'!$D12,'SO003'!$AL:$AL,5) -> 5001.2667
B13: SGCC | C13: 1.2 | D13: 1219 | E13: Coil | F13: =SUMIFS('SO003'!AI:AI,'SO003'!$AA:$AA,'Sum of data'!$B13,'SO003'!$AE:$AE,'Sum of data'!$C13,'SO003'!$AC:$AC,'Sum of data'!$D13,'SO003'!$AL:$AL,5) -> 45216.153 | G13: =SUMIFS('SO003'!AJ:AJ,'SO003'!$AA:$AA,'Sum of data'!$B13,'SO003'!$AE:$AE,'Sum of data'!$C13,'SO003'!$AC:$AC,'Sum of data'!$D13,'SO003'!$AL:$AL,5) -> 34179.79 | H13: =SUMIFS('SO003'!AK:AK,'SO003'!$AA:$AA,'Sum of data'!$B13,'SO003'!$AE:$AE,'Sum of data'!$C13,'SO003'!$AC:$AC,'Sum of data'!$D13,'SO003'!$AL:$AL,5) -> 11036.362
B14: SGCC | C14: 1.6 | D14: 1219 | E14: Z18 | F14: =SUMIFS('SO003'!AI:AI,'SO003'!$AA:$AA,'Sum of data'!$B14,'SO003'!$AE:$AE,'Sum of data'!$C14,'SO003'!$AC:$AC,'Sum of data'!$D14,'SO003'!$AL:$AL,5) -> 23256.087 | G14: =SUMIFS('SO003'!AJ:AJ,'SO003'!$AA:$AA,'Sum of data'!$B14,'SO003'!$AE:$AE,'Sum of data'!$C14,'SO003'!$AC:$AC,'Sum of data'!$D14,'SO003'!$AL:$AL,5) -> 9986.6778 | H14: =SUMIFS('SO003'!AK:AK,'SO003'!$AA:$AA,'Sum of data'!$B14,'SO003'!$AE:$AE,'Sum of data'!$C14,'SO003'!$AC:$AC,'Sum of data'!$D14,'SO003'!$AL:$AL,5) -> 13269.409
B15: SGCC | C15: 2 | D15: 1219 | E15: Z08 | F15: =SUMIFS('SO003'!AI:AI,'SO003'!$AA:$AA,'Sum of data'!$B15,'SO003'!$AE:$AE,'Sum of data'!$C15,'SO003'!$AC:$AC,'Sum of data'!$D15,'SO003'!$AL:$AL,5,'SO003'!$AB:$AB,'Sum of data'!$E15) -> 1318.3133 | G15: =SUMIFS('SO003'!AJ:AJ,'SO003'!$AA:$AA,'Sum of data'!$B15,'SO003'!$AE:$AE,'Sum of data'!$C15,'SO003'!$AC:$AC,'Sum of data'!$D15,'SO003'!$AL:$AL,5,'SO003'!$AB:$AB,'Sum of data'!$E15) -> 35.64528 | H15: =SUMIFS('SO003'!AK:AK,'SO003'!$AA:$AA,'Sum of data'!$B15,'SO003'!$AE:$AE,'Sum of data'!$C15,'SO003'!$AC:$AC,'Sum of data'!$D15,'SO003'!$AL:$AL,5,'SO003'!$AB:$AB,'Sum of data'!$E15) -> 1282.668
B16: SGCC | C16: 2 | D16: 1219 | E16: Z18 | F16: =SUMIFS('SO003'!AI:AI,'SO003'!$AA:$AA,'Sum of data'!$B16,'SO003'!$AE:$AE,'Sum of data'!$C16,'SO003'!$AC:$AC,'Sum of data'!$D16,'SO003'!$AL:$AL,5,'SO003'!$AB:$AB,'Sum of data'!$E16) -> 38412.153 | G16: =SUMIFS('SO003'!AJ:AJ,'SO003'!$AA:$AA,'Sum of data'!$B16,'SO003'!$AE:$AE,'Sum of data'!$C16,'SO003'!$AC:$AC,'Sum of data'!$D16,'SO003'!$AL:$AL,5,'SO003'!$AB:$AB,'Sum of data'!$E16) -> 20160.562 | H16: =SUMIFS('SO003'!AK:AK,'SO003'!$AA:$AA,'Sum of data'!$B16,'SO003'!$AE:$AE,'Sum of data'!$C16,'SO003'!$AC:$AC,'Sum of data'!$D16,'SO003'!$AL:$AL,5,'SO003'!$AB:$AB,'Sum of data'!$E16) -> 18251.591
B17: SGCC | C17: 2 | D17: 1219 | E17: Z22 | F17: =SUMIFS('SO003'!AI:AI,'SO003'!$AA:$AA,'Sum of data'!$B17,'SO003'!$AE:$AE,'Sum of data'!$C17,'SO003'!$AC:$AC,'Sum of data'!$D17,'SO003'!$AL:$AL,5,'SO003'!$AB:$AB,'Sum of data'!$E17) -> 36584.231 | G17: =SUMIFS('SO003'!AJ:AJ,'SO003'!$AA:$AA,'Sum of data'!$B17,'SO003'!$AE:$AE,'Sum of data'!$C17,'SO003'!$AC:$AC,'Sum of data'!$D17,'SO003'!$AL:$AL,5,'SO003'!$AB:$AB,'Sum of data'!$E17) -> 19060.678 | H17: =SUMIFS('SO003'!AK:AK,'SO003'!$AA:$AA,'Sum of data'!$B17,'SO003'!$AE:$AE,'Sum of data'!$C17,'SO003'!$AC:$AC,'Sum of data'!$D17,'SO003'!$AL:$AL,5,'SO003'!$AB:$AB,'Sum of data'!$E17) -> 17523.553
B18: Grand Total | F18: =SUM(F3:F17) -> 397649.44 | G18: =SUM(G3:G17) -> 277869.75 | H18: =SUM(H3:H17) -> 119779.69
B22: 2] Sum of Forcast
B24: Spec | C24: T | D24: W | E24: L/Coating | H24: ='Forecast WK20'!AF8 -> May'2026 | I24: ='Forecast WK20'!AG$8 -> YM202606 | J24: ='Forecast WK20'!AH$8 -> YM202607 | K24: ='Forecast WK20'!AI$8 -> YM202608 | L24: ='Forecast WK20'!AJ$8 -> YM202609 | M24: ='Forecast WK20'!AK$8 -> YM202610 | N24: ='Forecast WK20'!AL$8 -> YM202611 | O24: ='Forecast WK20'!AM$8 -> total
B25: SGCC | C25: 0.5 | D25: 1219 | E25: Coil | H25: =SUMIFS('Forecast WK20'!AF:AF,'Forecast WK20'!$W:$W,'Sum of data'!$B25,'Forecast WK20'!$AA:$AA,'Sum of data'!$C25,'Forecast WK20'!$Y:$Y,'Sum of data'!$D25) -> 9204.6587 | I25: =SUMIFS('Forecast WK20'!AG:AG,'Forecast WK20'!$W:$W,'Sum of data'!$B25,'Forecast WK20'!$AA:$AA,'Sum of data'!$C25,'Forecast WK20'!$Y:$Y,'Sum of data'!$D25) -> 11979.617 | J25: =SUMIFS('Forecast WK20'!AH:AH,'Forecast WK20'!$W:$W,'Sum of data'!$B25,'Forecast WK20'!$AA:$AA,'Sum of data'!$C25,'Forecast WK20'!$Y:$Y,'Sum of data'!$D25) -> 12081.368 | K25: =SUMIFS('Forecast WK20'!AI:AI,'Forecast WK20'!$W:$W,'Sum of data'!$B25,'Forecast WK20'!$AA:$AA,'Sum of data'!$C25,'Forecast WK20'!$Y:$Y,'Sum of data'!$D25) -> 13710.983 | L25: =SUMIFS('Forecast WK20'!AJ:AJ,'Forecast WK20'!$W:$W,'Sum of data'!$B25,'Forecast WK20'!$AA:$AA,'Sum of data'!$C25,'Forecast WK20'!$Y:$Y,'Sum of data'!$D25) -> 17635.713 | M25: =SUMIFS('Forecast WK20'!AK:AK,'Forecast WK20'!$W:$W,'Sum of data'!$B25,'Forecast WK20'!$AA:$AA,'Sum of data'!$C25,'Forecast WK20'!$Y:$Y,'Sum of data'!$D25) -> 446.31789 | N25: =SUMIFS('Forecast WK20'!AL:AL,'Forecast WK20'!$W:$W,'Sum of data'!$B25,'Forecast WK20'!$AA:$AA,'Sum of data'!$C25,'Forecast WK20'!$Y:$Y,'Sum of data'!$D25) -> 17703.282
B26: SGCC | C26: 0.6 | D26: 1219 | E26: Coil | H26: =SUMIFS('Forecast WK20'!AF:AF,'Forecast WK20'!$W:$W,'Sum of data'!$B26,'Forecast WK20'!$AA:$AA,'Sum of data'!$C26,'Forecast WK20'!$Y:$Y,'Sum of data'!$D26) -> 13767.385 | I26: =SUMIFS('Forecast WK20'!AG:AG,'Forecast WK20'!$W:$W,'Sum of data'!$B26,'Forecast WK20'!$AA:$AA,'Sum of data'!$C26,'Forecast WK20'!$Y:$Y,'Sum of data'!$D26) -> 24216.087 | J26: =SUMIFS('Forecast WK20'!AH:AH,'Forecast WK20'!$W:$W,'Sum of data'!$B26,'Forecast WK20'!$AA:$AA,'Sum of data'!$C26,'Forecast WK20'!$Y:$Y,'Sum of data'!$D26) -> 22345.812 | K26: =SUMIFS('Forecast WK20'!AI:AI,'Forecast WK20'!$W:$W,'Sum of data'!$B26,'Forecast WK20'!$AA:$AA,'Sum of data'!$C26,'Forecast WK20'!$Y:$Y,'Sum of data'!$D26) -> 22020.32 | L26: =SUMIFS('Forecast WK20'!AJ:AJ,'Forecast WK20'!$W:$W,'Sum of data'!$B26,'Forecast WK20'!$AA:$AA,'Sum of data'!$C26,'Forecast WK20'!$Y:$Y,'Sum of data'!$D26) -> 45866.023 | M26: =SUMIFS('Forecast WK20'!AK:AK,'Forecast WK20'!$W:$W,'Sum of data'!$B26,'Forecast WK20'!$AA:$AA,'Sum of data'!$C26,'Forecast WK20'!$Y:$Y,'Sum of data'!$D26) -> 4974.2104 | N26: =SUMIFS('Forecast WK20'!AL:AL,'Forecast WK20'!$W:$W,'Sum of data'!$B26,'Forecast WK20'!$AA:$AA,'Sum of data'!$C26,'Forecast WK20'!$Y:$Y,'Sum of data'!$D26) -> 31844.4
B27: SGCD | C27: 0.6 | D27: 1219 | E27: Coil | H27: =SUMIFS('Forecast WK20'!AF:AF,'Forecast WK20'!$W:$W,'Sum of data'!$B27,'Forecast WK20'!$AA:$AA,'Sum of data'!$C27,'Forecast WK20'!$Y:$Y,'Sum of data'!$D27) -> 1270.3214 | I27: =SUMIFS('Forecast WK20'!AG:AG,'Forecast WK20'!$W:$W,'Sum of data'!$B27,'Forecast WK20'!$AA:$AA,'Sum of data'!$C27,'Forecast WK20'!$Y:$Y,'Sum of data'!$D27) -> 3226.0641 | J27: =SUMIFS('Forecast WK20'!AH:AH,'Forecast WK20'!$W:$W,'Sum of data'!$B27,'Forecast WK20'!$AA:$AA,'Sum of data'!$C27,'Forecast WK20'!$Y:$Y,'Sum of data'!$D27) -> 3687.0946 | K27: =SUMIFS('Forecast WK20'!AI:AI,'Forecast WK20'!$W:$W,'Sum of data'!$B27,'Forecast WK20'!$AA:$AA,'Sum of data'!$C27,'Forecast WK20'!$Y:$Y,'Sum of data'!$D27) -> 3756.6106 | L27: =SUMIFS('Forecast WK20'!AJ:AJ,'Forecast WK20'!$W:$W,'Sum of data'!$B27,'Forecast WK20'!$AA:$AA,'Sum of data'!$C27,'Forecast WK20'!$Y:$Y,'Sum of data'!$D27) -> 7709.9234 | M27: =SUMIFS('Forecast WK20'!AK:AK,'Forecast WK20'!$W:$W,'Sum of data'!$B27,'Forecast WK20'!$AA:$AA,'Sum of data'!$C27,'Forecast WK20'!$Y:$Y,'Sum of data'!$D27) -> 0 | N27: =SUMIFS('Forecast WK20'!AL:AL,'Forecast WK20'!$W:$W,'Sum of data'!$B27,'Forecast WK20'!$AA:$AA,'Sum of data'!$C27,'Forecast WK20'!$Y:$Y,'Sum of data'!$D27) -> 4845.3994
B28: SGCD | C28: 0.6 | D28: 915 | E28: Coil | H28: =SUMIFS('Forecast WK20'!AF:AF,'Forecast WK20'!$W:$W,'Sum of data'!$B28,'Forecast WK20'!$AA:$AA,'Sum of data'!$C28,'Forecast WK20'!$Y:$Y,'Sum of data'!$D28) -> 17448.284 | I28: =SUMIFS('Forecast WK20'!AG:AG,'Forecast WK20'!$W:$W,'Sum of data'!$B28,'Forecast WK20'!$AA:$AA,'Sum of data'!$C28,'Forecast WK20'!$Y:$Y,'Sum of data'!$D28) -> 20612.527 | J28: =SUMIFS('Forecast WK20'!AH:AH,'Forecast WK20'!$W:$W,'Sum of data'!$B28,'Forecast WK20'!$AA:$AA,'Sum of data'!$C28,'Forecast WK20'!$Y:$Y,'Sum of data'!$D28) -> 16908.714 | K28: =SUMIFS('Forecast WK20'!AI:AI,'Forecast WK20'!$W:$W,'Sum of data'!$B28,'Forecast WK20'!$AA:$AA,'Sum of data'!$C28,'Forecast WK20'!$Y:$Y,'Sum of data'!$D28) -> 14171.113 | L28: =SUMIFS('Forecast WK20'!AJ:AJ,'Forecast WK20'!$W:$W,'Sum of data'!$B28,'Forecast WK20'!$AA:$AA,'Sum of data'!$C28,'Forecast WK20'!$Y:$Y,'Sum of data'!$D28) -> 40902.984 | M28: =SUMIFS('Forecast WK20'!AK:AK,'Forecast WK20'!$W:$W,'Sum of data'!$B28,'Forecast WK20'!$AA:$AA,'Sum of data'!$C28,'Forecast WK20'!$Y:$Y,'Sum of data'!$D28) -> 0 | N28: =SUMIFS('Forecast WK20'!AL:AL,'Forecast WK20'!$W:$W,'Sum of data'!$B28,'Forecast WK20'!$AA:$AA,'Sum of data'!$C28,'Forecast WK20'!$Y:$Y,'Sum of data'!$D28) -> 26248.765
B29: SGCD | C29: 0.6 | D29: 1340 | E29: Coil | H29: =SUMIFS('Forecast WK20'!AF:AF,'Forecast WK20'!$W:$W,'Sum of data'!$B29,'Forecast WK20'!$AA:$AA,'Sum of data'!$C29,'Forecast WK20'!$Y:$Y,'Sum of data'!$D29) -> 4605.2471 | I29: =SUMIFS('Forecast WK20'!AG:AG,'Forecast WK20'!$W:$W,'Sum of data'!$B29,'Forecast WK20'!$AA:$AA,'Sum of data'!$C29,'Forecast WK20'!$Y:$Y,'Sum of data'!$D29) -> 3872.5942 | J29: =SUMIFS('Forecast WK20'!AH:AH,'Forecast WK20'!$W:$W,'Sum of data'!$B29,'Forecast WK20'!$AA:$AA,'Sum of data'!$C29,'Forecast WK20'!$Y:$Y,'Sum of data'!$D29) -> 3349.2706 | K29: =SUMIFS('Forecast WK20'!AI:AI,'Forecast WK20'!$W:$W,'Sum of data'!$B29,'Forecast WK20'!$AA:$AA,'Sum of data'!$C29,'Forecast WK20'!$Y:$Y,'Sum of data'!$D29) -> 6593.8766 | L29: =SUMIFS('Forecast WK20'!AJ:AJ,'Forecast WK20'!$W:$W,'Sum of data'!$B29,'Forecast WK20'!$AA:$AA,'Sum of data'!$C29,'Forecast WK20'!$Y:$Y,'Sum of data'!$D29) -> 4196.482 | M29: =SUMIFS('Forecast WK20'!AK:AK,'Forecast WK20'!$W:$W,'Sum of data'!$B29,'Forecast WK20'!$AA:$AA,'Sum of data'!$C29,'Forecast WK20'!$Y:$Y,'Sum of data'!$D29) -> 0 | N29: =SUMIFS('Forecast WK20'!AL:AL,'Forecast WK20'!$W:$W,'Sum of data'!$B29,'Forecast WK20'!$AA:$AA,'Sum of data'!$C29,'Forecast WK20'!$Y:$Y,'Sum of data'!$D29) -> 7221.8648
B30: SGCC | C30: 0.7 | D30: 1219 | E30: Coil | H30: =SUMIFS('Forecast WK20'!AF:AF,'Forecast WK20'!$W:$W,'Sum of data'!$B30,'Forecast WK20'!$AA:$AA,'Sum of data'!$C30,'Forecast WK20'!$Y:$Y,'Sum of data'!$D30) -> 36404.261 | I30: =SUMIFS('Forecast WK20'!AG:AG,'Forecast WK20'!$W:$W,'Sum of data'!$B30,'Forecast WK20'!$AA:$AA,'Sum of data'!$C30,'Forecast WK20'!$Y:$Y,'Sum of data'!$D30) -> 46149.551 | J30: =SUMIFS('Forecast WK20'!AH:AH,'Forecast WK20'!$W:$W,'Sum of data'!$B30,'Forecast WK20'!$AA:$AA,'Sum of data'!$C30,'Forecast WK20'!$Y:$Y,'Sum of data'!$D30) -> 59802.289 | K30: =SUMIFS('Forecast WK20'!AI:AI,'Forecast WK20'!$W:$W,'Sum of data'!$B30,'Forecast WK20'!$AA:$AA,'Sum of data'!$C30,'Forecast WK20'!$Y:$Y,'Sum of data'!$D30) -> 28520.12 | L30: =SUMIFS('Forecast WK20'!AJ:AJ,'Forecast WK20'!$W:$W,'Sum of data'!$B30,'Forecast WK20'!$AA:$AA,'Sum of data'!$C30,'Forecast WK20'!$Y:$Y,'Sum of data'!$D30) -> 76112.855 | M30: =SUMIFS('Forecast WK20'!AK:AK,'Forecast WK20'!$W:$W,'Sum of data'!$B30,'Forecast WK20'!$AA:$AA,'Sum of data'!$C30,'Forecast WK20'!$Y:$Y,'Sum of data'!$D30) -> 10731.365 | N30: =SUMIFS('Forecast WK20'!AL:AL,'Forecast WK20'!$W:$W,'Sum of data'!$B30,'Forecast WK20'!$AA:$AA,'Sum of data'!$C30,'Forecast WK20'!$Y:$Y,'Sum of data'!$D30) -> 49090.341
B31: SGCC | C31: 0.8 | D31: 1219 | E31: Coil | H31: =SUMIFS('Forecast WK20'!AF:AF,'Forecast WK20'!$W:$W,'Sum of data'!$B31,'Forecast WK20'!$AA:$AA,'Sum of data'!$C31,'Forecast WK20'!$Y:$Y,'Sum of data'!$D31) -> 27348.244 | I31: =SUMIFS('Forecast WK20'!AG:AG,'Forecast WK20'!$W:$W,'Sum of data'!$B31,'Forecast WK20'!$AA:$AA,'Sum of data'!$C31,'Forecast WK20'!$Y:$Y,'Sum of data'!$D31) -> 45104.969 | J31: =SUMIFS('Forecast WK20'!AH:AH,'Forecast WK20'!$W:$W,'Sum of data'!$B31,'Forecast WK20'!$AA:$AA,'Sum of data'!$C31,'Forecast WK20'!$Y:$Y,'Sum of data'!$D31) -> 44257.407 | K31: =SUMIFS('Forecast WK20'!AI:AI,'Forecast WK20'!$W:$W,'Sum of data'!$B31,'Forecast WK20'!$AA:$AA,'Sum of data'!$C31,'Forecast WK20'!$Y:$Y,'Sum of data'!$D31) -> 46142.297 | L31: =SUMIFS('Forecast WK20'!AJ:AJ,'Forecast WK20'!$W:$W,'Sum of data'!$B31,'Forecast WK20'!$AA:$AA,'Sum of data'!$C31,'Forecast WK20'!$Y:$Y,'Sum of data'!$D31) -> 82059.969 | M31: =SUMIFS('Forecast WK20'!AK:AK,'Forecast WK20'!$W:$W,'Sum of data'!$B31,'Forecast WK20'!$AA:$AA,'Sum of data'!$C31,'Forecast WK20'!$Y:$Y,'Sum of data'!$D31) -> 6391.1899 | N31: =SUMIFS('Forecast WK20'!AL:AL,'Forecast WK20'!$W:$W,'Sum of data'!$B31,'Forecast WK20'!$AA:$AA,'Sum of data'!$C31,'Forecast WK20'!$Y:$Y,'Sum of data'!$D31) -> 59757.658
B32: SGCD | C32: 0.8 | D32: 1219 | E32: Coil | H32: =SUMIFS('Forecast WK20'!AF:AF,'Forecast WK20'!$W:$W,'Sum of data'!$B32,'Forecast WK20'!$AA:$AA,'Sum of data'!$C32,'Forecast WK20'!$Y:$Y,'Sum of data'!$D32) -> 341.45179 | I32: =SUMIFS('Forecast WK20'!AG:AG,'Forecast WK20'!$W:$W,'Sum of data'!$B32,'Forecast WK20'!$AA:$AA,'Sum of data'!$C32,'Forecast WK20'!$Y:$Y,'Sum of data'!$D32) -> 287.76005 | J32: =SUMIFS('Forecast WK20'!AH:AH,'Forecast WK20'!$W:$W,'Sum of data'!$B32,'Forecast WK20'!$AA:$AA,'Sum of data'!$C32,'Forecast WK20'!$Y:$Y,'Sum of data'!$D32) -> 241.02479 | K32: =SUMIFS('Forecast WK20'!AI:AI,'Forecast WK20'!$W:$W,'Sum of data'!$B32,'Forecast WK20'!$AA:$AA,'Sum of data'!$C32,'Forecast WK20'!$Y:$Y,'Sum of data'!$D32) -> 482.04958 | L32: =SUMIFS('Forecast WK20'!AJ:AJ,'Forecast WK20'!$W:$W,'Sum of data'!$B32,'Forecast WK20'!$AA:$AA,'Sum of data'!$C32,'Forecast WK20'!$Y:$Y,'Sum of data'!$D32) -> 321.36639 | M32: =SUMIFS('Forecast WK20'!AK:AK,'Forecast WK20'!$W:$W,'Sum of data'!$B32,'Forecast WK20'!$AA:$AA,'Sum of data'!$C32,'Forecast WK20'!$Y:$Y,'Sum of data'!$D32) -> 0 | N32: =SUMIFS('Forecast WK20'!AL:AL,'Forecast WK20'!$W:$W,'Sum of data'!$B32,'Forecast WK20'!$AA:$AA,'Sum of data'!$C32,'Forecast WK20'!$Y:$Y,'Sum of data'!$D32) -> 542.30578
B33: SGCD | C33: 0.8 | D33: 935 | E33: Z22 | H33: =SUMIFS('Forecast WK20'!AF:AF,'Forecast WK20'!$W:$W,'Sum of data'!$B33,'Forecast WK20'!$AA:$AA,'Sum of data'!$C33,'Forecast WK20'!$Y:$Y,'Sum of data'!$D33) -> 14811.254 | I33: =SUMIFS('Forecast WK20'!AG:AG,'Forecast WK20'!$W:$W,'Sum of data'!$B33,'Forecast WK20'!$AA:$AA,'Sum of data'!$C33,'Forecast WK20'!$Y:$Y,'Sum of data'!$D33) -> 29622.509 | J33: =SUMIFS('Forecast WK20'!AH:AH,'Forecast WK20'!$W:$W,'Sum of data'!$B33,'Forecast WK20'!$AA:$AA,'Sum of data'!$C33,'Forecast WK20'!$Y:$Y,'Sum of data'!$D33) -> 16662.661 | K33: =SUMIFS('Forecast WK20'!AI:AI,'Forecast WK20'!$W:$W,'Sum of data'!$B33,'Forecast WK20'!$AA:$AA,'Sum of data'!$C33,'Forecast WK20'!$Y:$Y,'Sum of data'!$D33) -> 14811.254 | L33: =SUMIFS('Forecast WK20'!AJ:AJ,'Forecast WK20'!$W:$W,'Sum of data'!$B33,'Forecast WK20'!$AA:$AA,'Sum of data'!$C33,'Forecast WK20'!$Y:$Y,'Sum of data'!$D33) -> 18514.068 | M33: =SUMIFS('Forecast WK20'!AK:AK,'Forecast WK20'!$W:$W,'Sum of data'!$B33,'Forecast WK20'!$AA:$AA,'Sum of data'!$C33,'Forecast WK20'!$Y:$Y,'Sum of data'!$D33) -> 20365.475 | N33: =SUMIFS('Forecast WK20'!AL:AL,'Forecast WK20'!$W:$W,'Sum of data'!$B33,'Forecast WK20'!$AA:$AA,'Sum of data'!$C33,'Forecast WK20'!$Y:$Y,'Sum of data'!$D33) -> 20365.475
B34: SGCC | C34: 1 | D34: 1219 | E34: Coil | H34: =SUMIFS('Forecast WK20'!AF:AF,'Forecast WK20'!$W:$W,'Sum of data'!$B34,'Forecast WK20'!$AA:$AA,'Sum of data'!$C34,'Forecast WK20'!$Y:$Y,'Sum of data'!$D34) -> 9517.3107 | I34: =SUMIFS('Forecast WK20'!AG:AG,'Forecast WK20'!$W:$W,'Sum of data'!$B34,'Forecast WK20'!$AA:$AA,'Sum of data'!$C34,'Forecast WK20'!$Y:$Y,'Sum of data'!$D34) -> 9402.5236 | J34: =SUMIFS('Forecast WK20'!AH:AH,'Forecast WK20'!$W:$W,'Sum of data'!$B34,'Forecast WK20'!$AA:$AA,'Sum of data'!$C34,'Forecast WK20'!$Y:$Y,'Sum of data'!$D34) -> 13227.861 | K34: =SUMIFS('Forecast WK20'!AI:AI,'Forecast WK20'!$W:$W,'Sum of data'!$B34,'Forecast WK20'!$AA:$AA,'Sum of data'!$C34,'Forecast WK20'!$Y:$Y,'Sum of data'!$D34) -> 8835.7995 | L34: =SUMIFS('Forecast WK20'!AJ:AJ,'Forecast WK20'!$W:$W,'Sum of data'!$B34,'Forecast WK20'!$AA:$AA,'Sum of data'!$C34,'Forecast WK20'!$Y:$Y,'Sum of data'!$D34) -> 18180.306 | M34: =SUMIFS('Forecast WK20'!AK:AK,'Forecast WK20'!$W:$W,'Sum of data'!$B34,'Forecast WK20'!$AA:$AA,'Sum of data'!$C34,'Forecast WK20'!$Y:$Y,'Sum of data'!$D34) -> 3407.3931 | N34: =SUMIFS('Forecast WK20'!AL:AL,'Forecast WK20'!$W:$W,'Sum of data'!$B34,'Forecast WK20'!$AA:$AA,'Sum of data'!$C34,'Forecast WK20'!$Y:$Y,'Sum of data'!$D34) -> 12992.721
B35: SGCC | C35: 1.2 | D35: 1219 | E35: Coil | H35: =SUMIFS('Forecast WK20'!AF:AF,'Forecast WK20'!$W:$W,'Sum of data'!$B35,'Forecast WK20'!$AA:$AA,'Sum of data'!$C35,'Forecast WK20'!$Y:$Y,'Sum of data'!$D35) -> 20827.399 | I35: =SUMIFS('Forecast WK20'!AG:AG,'Forecast WK20'!$W:$W,'Sum of data'!$B35,'Forecast WK20'!$AA:$AA,'Sum of data'!$C35,'Forecast WK20'!$Y:$Y,'Sum of data'!$D35) -> 39446.357 | J35: =SUMIFS('Forecast WK20'!AH:AH,'Forecast WK20'!$W:$W,'Sum of data'!$B35,'Forecast WK20'!$AA:$AA,'Sum of data'!$C35,'Forecast WK20'!$Y:$Y,'Sum of data'!$D35) -> 30521.695 | K35: =SUMIFS('Forecast WK20'!AI:AI,'Forecast WK20'!$W:$W,'Sum of data'!$B35,'Forecast WK20'!$AA:$AA,'Sum of data'!$C35,'Forecast WK20'!$Y:$Y,'Sum of data'!$D35) -> 23984.152 | L35: =SUMIFS('Forecast WK20'!AJ:AJ,'Forecast WK20'!$W:$W,'Sum of data'!$B35,'Forecast WK20'!$AA:$AA,'Sum of data'!$C35,'Forecast WK20'!$Y:$Y,'Sum of data'!$D35) -> 43353.674 | M35: =SUMIFS('Forecast WK20'!AK:AK,'Forecast WK20'!$W:$W,'Sum of data'!$B35,'Forecast WK20'!$AA:$AA,'Sum of data'!$C35,'Forecast WK20'!$Y:$Y,'Sum of data'!$D35) -> 22675.465 | N35: =SUMIFS('Forecast WK20'!AL:AL,'Forecast WK20'!$W:$W,'Sum of data'!$B35,'Forecast WK20'!$AA:$AA,'Sum of data'!$C35,'Forecast WK20'!$Y:$Y,'Sum of data'!$D35) -> 24161.415
B36: SGCC | C36: 1.6 | D36: 1219 | E36: Z18 | H36: =SUMIFS('Forecast WK20'!AF:AF,'Forecast WK20'!$W:$W,'Sum of data'!$B36,'Forecast WK20'!$AA:$AA,'Sum of data'!$C36,'Forecast WK20'!$Y:$Y,'Sum of data'!$D36) -> 11379.52 | I36: =SUMIFS('Forecast WK20'!AG:AG,'Forecast WK20'!$W:$W,'Sum of data'!$B36,'Forecast WK20'!$AA:$AA,'Sum of data'!$C36,'Forecast WK20'!$Y:$Y,'Sum of data'!$D36) -> 22496.04 | J36: =SUMIFS('Forecast WK20'!AH:AH,'Forecast WK20'!$W:$W,'Sum of data'!$B36,'Forecast WK20'!$AA:$AA,'Sum of data'!$C36,'Forecast WK20'!$Y:$Y,'Sum of data'!$D36) -> 20423.827 | K36: =SUMIFS('Forecast WK20'!AI:AI,'Forecast WK20'!$W:$W,'Sum of data'!$B36,'Forecast WK20'!$AA:$AA,'Sum of data'!$C36,'Forecast WK20'!$Y:$Y,'Sum of data'!$D36) -> 17388.183 | L36: =SUMIFS('Forecast WK20'!AJ:AJ,'Forecast WK20'!$W:$W,'Sum of data'!$B36,'Forecast WK20'!$AA:$AA,'Sum of data'!$C36,'Forecast WK20'!$Y:$Y,'Sum of data'!$D36) -> 48781.652 | M36: =SUMIFS('Forecast WK20'!AK:AK,'Forecast WK20'!$W:$W,'Sum of data'!$B36,'Forecast WK20'!$AA:$AA,'Sum of data'!$C36,'Forecast WK20'!$Y:$Y,'Sum of data'!$D36) -> 0 | N36: =SUMIFS('Forecast WK20'!AL:AL,'Forecast WK20'!$W:$W,'Sum of data'!$B36,'Forecast WK20'!$AA:$AA,'Sum of data'!$C36,'Forecast WK20'!$Y:$Y,'Sum of data'!$D36) -> 25928.947
B37: SGCC | C37: 2 | D37: 1219 | E37: Z08 | H37: =SUMIFS('Forecast WK20'!AF:AF,'Forecast WK20'!$W:$W,'Sum of data'!$B37,'Forecast WK20'!$AA:$AA,'Sum of data'!$C37,'Forecast WK20'!$Y:$Y,'Sum of data'!$D37,'Forecast WK20'!$X:$X,'Sum of data'!$E37) -> 640.66392 | I37: =SUMIFS('Forecast WK20'!AG:AG,'Forecast WK20'!$W:$W,'Sum of data'!$B37,'Forecast WK20'!$AA:$AA,'Sum of data'!$C37,'Forecast WK20'!$Y:$Y,'Sum of data'!$D37,'Forecast WK20'!$X:$X,'Sum of data'!$E37) -> 1530.4936 | J37: =SUMIFS('Forecast WK20'!AH:AH,'Forecast WK20'!$W:$W,'Sum of data'!$B37,'Forecast WK20'!$AA:$AA,'Sum of data'!$C37,'Forecast WK20'!$Y:$Y,'Sum of data'!$D37,'Forecast WK20'!$X:$X,'Sum of data'!$E37) -> 831.19384 | K37: =SUMIFS('Forecast WK20'!AI:AI,'Forecast WK20'!$W:$W,'Sum of data'!$B37,'Forecast WK20'!$AA:$AA,'Sum of data'!$C37,'Forecast WK20'!$Y:$Y,'Sum of data'!$D37,'Forecast WK20'!$X:$X,'Sum of data'!$E37) -> 836.03301 | L37: =SUMIFS('Forecast WK20'!AJ:AJ,'Forecast WK20'!$W:$W,'Sum of data'!$B37,'Forecast WK20'!$AA:$AA,'Sum of data'!$C37,'Forecast WK20'!$Y:$Y,'Sum of data'!$D37,'Forecast WK20'!$X:$X,'Sum of data'!$E37) -> 2390.3858 | M37: =SUMIFS('Forecast WK20'!AK:AK,'Forecast WK20'!$W:$W,'Sum of data'!$B37,'Forecast WK20'!$AA:$AA,'Sum of data'!$C37,'Forecast WK20'!$Y:$Y,'Sum of data'!$D37,'Forecast WK20'!$X:$X,'Sum of data'!$E37) -> 0 | N37: =SUMIFS('Forecast WK20'!AL:AL,'Forecast WK20'!$W:$W,'Sum of data'!$B37,'Forecast WK20'!$AA:$AA,'Sum of data'!$C37,'Forecast WK20'!$Y:$Y,'Sum of data'!$D37,'Forecast WK20'!$X:$X,'Sum of data'!$E37) -> 1605.2182
B38: SGCC | C38: 2 | D38: 1219 | E38: Z18 | H38: =SUMIFS('Forecast WK20'!AF:AF,'Forecast WK20'!$W:$W,'Sum of data'!$B38,'Forecast WK20'!$AA:$AA,'Sum of data'!$C38,'Forecast WK20'!$Y:$Y,'Sum of data'!$D38,'Forecast WK20'!$X:$X,'Sum of data'!$E38) -> 28397.906 | I38: =SUMIFS('Forecast WK20'!AG:AG,'Forecast WK20'!$W:$W,'Sum of data'!$B38,'Forecast WK20'!$AA:$AA,'Sum of data'!$C38,'Forecast WK20'!$Y:$Y,'Sum of data'!$D38,'Forecast WK20'!$X:$X,'Sum of data'!$E38) -> 36538.477 | J38: =SUMIFS('Forecast WK20'!AH:AH,'Forecast WK20'!$W:$W,'Sum of data'!$B38,'Forecast WK20'!$AA:$AA,'Sum of data'!$C38,'Forecast WK20'!$Y:$Y,'Sum of data'!$D38,'Forecast WK20'!$X:$X,'Sum of data'!$E38) -> 45234.339 | K38: =SUMIFS('Forecast WK20'!AI:AI,'Forecast WK20'!$W:$W,'Sum of data'!$B38,'Forecast WK20'!$AA:$AA,'Sum of data'!$C38,'Forecast WK20'!$Y:$Y,'Sum of data'!$D38,'Forecast WK20'!$X:$X,'Sum of data'!$E38) -> 30909.72 | L38: =SUMIFS('Forecast WK20'!AJ:AJ,'Forecast WK20'!$W:$W,'Sum of data'!$B38,'Forecast WK20'!$AA:$AA,'Sum of data'!$C38,'Forecast WK20'!$Y:$Y,'Sum of data'!$D38,'Forecast WK20'!$X:$X,'Sum of data'!$E38) -> 56761.017 | M38: =SUMIFS('Forecast WK20'!AK:AK,'Forecast WK20'!$W:$W,'Sum of data'!$B38,'Forecast WK20'!$AA:$AA,'Sum of data'!$C38,'Forecast WK20'!$Y:$Y,'Sum of data'!$D38,'Forecast WK20'!$X:$X,'Sum of data'!$E38) -> 3892.9159 | N38: =SUMIFS('Forecast WK20'!AL:AL,'Forecast WK20'!$W:$W,'Sum of data'!$B38,'Forecast WK20'!$AA:$AA,'Sum of data'!$C38,'Forecast WK20'!$Y:$Y,'Sum of data'!$D38,'Forecast WK20'!$X:$X,'Sum of data'!$E38) -> 46728.281
B39: SGCC | C39: 2 | D39: 1219 | E39: Z22 | H39: =SUMIFS('Forecast WK20'!AF:AF,'Forecast WK20'!$W:$W,'Sum of data'!$B39,'Forecast WK20'!$AA:$AA,'Sum of data'!$C39,'Forecast WK20'!$Y:$Y,'Sum of data'!$D39,'Forecast WK20'!$X:$X,'Sum of data'!$E39) -> 19555.581 | I39: =SUMIFS('Forecast WK20'!AG:AG,'Forecast WK20'!$W:$W,'Sum of data'!$B39,'Forecast WK20'!$AA:$AA,'Sum of data'!$C39,'Forecast WK20'!$Y:$Y,'Sum of data'!$D39,'Forecast WK20'!$X:$X,'Sum of data'!$E39) -> 17918.196 | J39: =SUMIFS('Forecast WK20'!AH:AH,'Forecast WK20'!$W:$W,'Sum of data'!$B39,'Forecast WK20'!$AA:$AA,'Sum of data'!$C39,'Forecast WK20'!$Y:$Y,'Sum of data'!$D39,'Forecast WK20'!$X:$X,'Sum of data'!$E39) -> 15728.35 | K39: =SUMIFS('Forecast WK20'!AI:AI,'Forecast WK20'!$W:$W,'Sum of data'!$B39,'Forecast WK20'!$AA:$AA,'Sum of data'!$C39,'Forecast WK20'!$Y:$Y,'Sum of data'!$D39,'Forecast WK20'!$X:$X,'Sum of data'!$E39) -> 15664.061 | L39: =SUMIFS('Forecast WK20'!AJ:AJ,'Forecast WK20'!$W:$W,'Sum of data'!$B39,'Forecast WK20'!$AA:$AA,'Sum of data'!$C39,'Forecast WK20'!$Y:$Y,'Sum of data'!$D39,'Forecast WK20'!$X:$X,'Sum of data'!$E39) -> 36943.974 | M39: =SUMIFS('Forecast WK20'!AK:AK,'Forecast WK20'!$W:$W,'Sum of data'!$B39,'Forecast WK20'!$AA:$AA,'Sum of data'!$C39,'Forecast WK20'!$Y:$Y,'Sum of data'!$D39,'Forecast WK20'!$X:$X,'Sum of data'!$E39) -> 387.67775 | N39: =SUMIFS('Forecast WK20'!AL:AL,'Forecast WK20'!$W:$W,'Sum of data'!$B39,'Forecast WK20'!$AA:$AA,'Sum of data'!$C39,'Forecast WK20'!$Y:$Y,'Sum of data'!$D39,'Forecast WK20'!$X:$X,'Sum of data'!$E39) -> 22821.792
B40: Grand Total | H40: =SUM(H25:H39) -> 215519.49 | I40: =SUM(I25:I39) -> 312403.77 | J40: =SUM(J25:J39) -> 305302.91 | K40: =SUM(K25:K39) -> 247826.57 | L40: =SUM(L25:L39) -> 499730.39 | M40: =SUM(M25:M39) -> 73272.01 | N40: =SUM(N25:N39) -> 351857.87
B43: 3] Sum of Stock (include ANGANG)
B44: Spec | C44: T | D44: W | E44: L | F44: MCGD | G44: MCB-HOLD | H44: MCCB | I44: MCDN | J44: MCRT | K44: FGGD | L44: FGNG | M44: FGB | N44: FGHOLD | O44: FGREMARK | P44: STRAPING | Q44: SAMPLE | R44: FGSP | S44: FGTE | U44: Total | V44: Available stock
B45: SGCC | C45: 0.5 | D45: 1219 | E45: Coil | F45: =SUMIFS('Stock 18.05.02'!$AE:$AE,'Stock 18.05.02'!$BH:$BH,'Sum of data'!$B45,'Stock 18.05.02'!$P:$P,'Sum of data'!$C45,'Stock 18.05.02'!$BJ:$BJ,'Sum of data'!$D45,'Stock 18.05.02'!$AG:$AG,'Sum of data'!F$44) -> 6940 | G45: =SUMIFS('Stock 18.05.02'!$AE:$AE,'Stock 18.05.02'!$BH:$BH,'Sum of data'!$B45,'Stock 18.05.02'!$P:$P,'Sum of data'!$C45,'Stock 18.05.02'!$BJ:$BJ,'Sum of data'!$D45,'Stock 18.05.02'!$AG:$AG,'Sum of data'!G$44) -> 0 | H45: =SUMIFS('Stock 18.05.02'!$AE:$AE,'Stock 18.05.02'!$BH:$BH,'Sum of data'!$B45,'Stock 18.05.02'!$P:$P,'Sum of data'!$C45,'Stock 18.05.02'!$BJ:$BJ,'Sum of data'!$D45,'Stock 18.05.02'!$AG:$AG,'Sum of data'!H$44) -> 1590 | I45: =SUMIFS('Stock 18.05.02'!$AE:$AE,'Stock 18.05.02'!$BH:$BH,'Sum of data'!$B45,'Stock 18.05.02'!$P:$P,'Sum of data'!$C45,'Stock 18.05.02'!$BJ:$BJ,'Sum of data'!$D45,'Stock 18.05.02'!$AG:$AG,'Sum of data'!I$44) -> 7085 | J45: =SUMIFS('Stock 18.05.02'!$AE:$AE,'Stock 18.05.02'!$BH:$BH,'Sum of data'!$B45,'Stock 18.05.02'!$P:$P,'Sum of data'!$C45,'Stock 18.05.02'!$BJ:$BJ,'Sum of data'!$D45,'Stock 18.05.02'!$AG:$AG,'Sum of data'!J$44) -> 8205 | K45: =SUMIFS('Stock 18.05.02'!$AE:$AE,'Stock 18.05.02'!$BH:$BH,'Sum of data'!$B45,'Stock 18.05.02'!$P:$P,'Sum of data'!$C45,'Stock 18.05.02'!$BJ:$BJ,'Sum of data'!$D45,'Stock 18.05.02'!$AG:$AG,'Sum of data'!K$44) -> 10043 | L45: =SUMIFS('Stock 18.05.02'!$AE:$AE,'Stock 18.05.02'!$BH:$BH,'Sum of data'!$B45,'Stock 18.05.02'!$P:$P,'Sum of data'!$C45,'Stock 18.05.02'!$BJ:$BJ,'Sum of data'!$D45,'Stock 18.05.02'!$AG:$AG,'Sum of data'!L$44) -> 195 | M45: =SUMIFS('Stock 18.05.02'!$AE:$AE,'Stock 18.05.02'!$BH:$BH,'Sum of data'!$B45,'Stock 18.05.02'!$P:$P,'Sum of data'!$C45,'Stock 18.05.02'!$BJ:$BJ,'Sum of data'!$D45,'Stock 18.05.02'!$AG:$AG,'Sum of data'!M$44) -> 3064 | ... T45: =SUMIFS('Stock 18.05.02'!$AE:$AE,'Stock 18.05.02'!$BH:$BH,'Sum of data'!$B45,'Stock 18.05.02'!$P:$P,'Sum of data'!$C45,'Stock 18.05.02'!$BJ:$BJ,'Sum of data'!$D45,'Stock 18.05.02'!$AG:$AG,'Sum of data'!T$44) -> 0 | U45: =SUM(F45:T45) -> 38188 | V45: =SUM(F45:J45) -> 23820
B46: SGCC | C46: 0.6 | D46: 1219 | E46: Coil | F46: =SUMIFS('Stock 18.05.02'!$AE:$AE,'Stock 18.05.02'!$BH:$BH,'Sum of data'!$B46,'Stock 18.05.02'!$P:$P,'Sum of data'!$C46,'Stock 18.05.02'!$BJ:$BJ,'Sum of data'!$D46,'Stock 18.05.02'!$AG:$AG,'Sum of data'!F$44) -> 23375 | G46: =SUMIFS('Stock 18.05.02'!$AE:$AE,'Stock 18.05.02'!$BH:$BH,'Sum of data'!$B46,'Stock 18.05.02'!$P:$P,'Sum of data'!$C46,'Stock 18.05.02'!$BJ:$BJ,'Sum of data'!$D46,'Stock 18.05.02'!$AG:$AG,'Sum of data'!G$44) -> 0 | H46: =SUMIFS('Stock 18.05.02'!$AE:$AE,'Stock 18.05.02'!$BH:$BH,'Sum of data'!$B46,'Stock 18.05.02'!$P:$P,'Sum of data'!$C46,'Stock 18.05.02'!$BJ:$BJ,'Sum of data'!$D46,'Stock 18.05.02'!$AG:$AG,'Sum of data'!H$44) -> 15217 | I46: =SUMIFS('Stock 18.05.02'!$AE:$AE,'Stock 18.05.02'!$BH:$BH,'Sum of data'!$B46,'Stock 18.05.02'!$P:$P,'Sum of data'!$C46,'Stock 18.05.02'!$BJ:$BJ,'Sum of data'!$D46,'Stock 18.05.02'!$AG:$AG,'Sum of data'!I$44) -> 0 | J46: =SUMIFS('Stock 18.05.02'!$AE:$AE,'Stock 18.05.02'!$BH:$BH,'Sum of data'!$B46,'Stock 18.05.02'!$P:$P,'Sum of data'!$C46,'Stock 18.05.02'!$BJ:$BJ,'Sum of data'!$D46,'Stock 18.05.02'!$AG:$AG,'Sum of data'!J$44) -> 14525 | K46: =SUMIFS('Stock 18.05.02'!$AE:$AE,'Stock 18.05.02'!$BH:$BH,'Sum of data'!$B46,'Stock 18.05.02'!$P:$P,'Sum of data'!$C46,'Stock 18.05.02'!$BJ:$BJ,'Sum of data'!$D46,'Stock 18.05.02'!$AG:$AG,'Sum of data'!K$44) -> 12668.6 | L46: =SUMIFS('Stock 18.05.02'!$AE:$AE,'Stock 18.05.02'!$BH:$BH,'Sum of data'!$B46,'Stock 18.05.02'!$P:$P,'Sum of data'!$C46,'Stock 18.05.02'!$BJ:$BJ,'Sum of data'!$D46,'Stock 18.05.02'!$AG:$AG,'Sum of data'!L$44) -> 221 | M46: =SUMIFS('Stock 18.05.02'!$AE:$AE,'Stock 18.05.02'!$BH:$BH,'Sum of data'!$B46,'Stock 18.05.02'!$P:$P,'Sum of data'!$C46,'Stock 18.05.02'!$BJ:$BJ,'Sum of data'!$D46,'Stock 18.05.02'!$AG:$AG,'Sum of data'!M$44) -> 9770 | ... T46: =SUMIFS('Stock 18.05.02'!$AE:$AE,'Stock 18.05.02'!$BH:$BH,'Sum of data'!$B46,'Stock 18.05.02'!$P:$P,'Sum of data'!$C46,'Stock 18.05.02'!$BJ:$BJ,'Sum of data'!$D46,'Stock 18.05.02'!$AG:$AG,'Sum of data'!T$44) -> 0 | U46: =SUM(F46:T46) -> 78501.6 | V46: =SUM(F46:J46) -> 53117
...

Sheet Forecast WK20
W5: PTT | AF5: =SUBTOTAL(9,AF9:AF1962) -> 215519.49 | AG5: =SUBTOTAL(9,AG9:AG1962) -> 312403.77 | AH5: =SUBTOTAL(9,AH9:AH1962) -> 305302.91 | AI5: =SUBTOTAL(9,AI9:AI1962) -> 247826.57 | AJ5: =SUBTOTAL(9,AJ9:AJ1962) -> 499730.39 | AK5: =SUBTOTAL(9,AK9:AK1962) -> 73272.01 | AL5: =SUBTOTAL(9,AL9:AL1962) -> 351857.87
B6: Foecast WK 20/2026 | E6: M-2 | F6: M+1 | J6: M+2 | N6: Actual balance PO
B8: Vendor | C8: MaterialNo | D8: Description | E8: W | F8: W15 | G8: W16 | H8: W17 | I8: W18 | J8: W19 | K8: W20 | L8: W21 | M8: W22 | N8: YM202606 | O8: YM202607 | P8: YM202608 | Q8: YM202609 | R8: YM202610 | S8: YM202611 | T8: total | U8: Period | W8: Spec | X8: Coating | Y8: MC Width | Z8: Spec | AA8: T | AB8: W | AC8: L | AD8: Kg/Pc | AF8: May'2026 | AG8: =N8 -> YM202606 | AH8: =O8 -> YM202607 | AI8: =P8 -> YM202608 | AJ8: =Q8 -> YM202609 | AK8: =R8 -> YM202610 | AL8: =S8 -> YM202611 | AM8: =T8 -> total
B9: LP0047 | C9: G0011030001529E | D9: SGCC-ZSBX-Z08 : 1.0*85*185 CHR-FREE | E9: 0 | F9: 0 | G9: 0 | H9: 0 | I9: 0 | J9: 0 | K9: 0 | L9: 0 | M9: 0 | N9: 87.4 | O9: 482.4 | P9: 201 | Q9: 844.2 | R9: 0 | S9: 522.6 | T9: 2137.6 | U9: Delivery | W9: =_xlfn.XLOOKUP($C9,'Master list'!$C:$C,'Master list'!E:E) -> SGCC | X9: =_xlfn.XLOOKUP($C9,'Master list'!$C:$C,'Master list'!F:F) -> Z08 | Y9: =_xlfn.XLOOKUP($C9,'Master list'!$C:$C,'Master list'!O:O) -> 1219 | Z9: =VLOOKUP($C9,'Master list'!$C:$Z,5,0) -> SGCC-ZSBX-Z08 | AA9: =VLOOKUP($C9,'Master list'!$C:$Z,6,0) -> 1 | AB9: =VLOOKUP($C9,'Master list'!$C:$Z,7,0) -> 85 | AC9: =VLOOKUP($C9,'Master list'!$C:$Z,8,0) -> 185 | AD9: =VLOOKUP($C9,'Master list'!$C:$Z,9,0) -> 0.12344125 | AF9: =SUM(J9:M9)*AD9 -> 0 | AG9: =$AD9*N9 -> 10.788765 | AH9: =$AD9*O9 -> 59.548059 | AI9: =$AD9*P9 -> 24.811691 | AJ9: =$AD9*Q9 -> 104.2091 | AK9: =$AD9*R9 -> 0 | AL9: =$AD9*S9 -> 64.510397 | AM9: =$AD9*T9 -> 263.86802
B10: LP0047 | C10: G0011030001529ETD | D10: SGCC-ZSBX-Z08 : 1.0*85*185 CHR-FREE | E10: 0 | F10: 0 | G10: 0 | H10: 0 | I10: 0 | J10: 0 | K10: 0 | L10: 0 | M10: 0 | N10: 1687.6 | O10: 1567.8 | P10: 884.4 | Q10: 3658.2 | R10: 0 | S10: 1889.4 | T10: 9687.4 | U10: Delivery | W10: =_xlfn.XLOOKUP($C10,'Master list'!$C:$C,'Master list'!E:E) -> SGCC | X10: =VLOOKUP($C10,'Master list'!$C:$Z,4,0) -> Z08 | Y10: =_xlfn.XLOOKUP($C10,'Master list'!$C:$C,'Master list'!O:O) -> 1219 | Z10: =VLOOKUP($C10,'Master list'!$C:$Z,5,0) -> SGCC-ZSBX-Z08 | AA10: =VLOOKUP($C10,'Master list'!$C:$Z,6,0) -> 1 | AB10: =VLOOKUP($C10,'Master list'!$C:$Z,7,0) -> 85 | AC10: =VLOOKUP($C10,'Master list'!$C:$Z,8,0) -> 185 | AD10: =VLOOKUP($C10,'Master list'!$C:$Z,9,0) -> 0.12344125 | AF10: =SUM(J10:M10)*AD10 -> 0 | AG10: =$AD10*N10 -> 208.31945 | AH10: =$AD10*O10 -> 193.53119 | AI10: =$AD10*P10 -> 109.17144 | AJ10: =$AD10*Q10 -> 451.57278 | AK10: =$AD10*R10 -> 0 | AL10: =$AD10*S10 -> 233.2299 | AM10: =$AD10*T10 -> 1195.8248
