Workbook
Name _aug08: #REF!
Name _kat1: #REF!
Name _oct1: #REF!
Name a: #REF!
Name AA: #REF!
Name aaa: #REF!
Name aaaa: #REF!
Name AAAAA: #REF!
Name AAAAAA: #REF!
Name actual: #REF!
Name AD: #REF!
Name AHMAD: #REF!
Name ALL: #REF!
Name AM: #REF!
Name b: #REF!
Name BASE: #REF!
Name baseprice: #REF!
Name bb: #REF!
Name BBB: #REF!
Name BLANK: #REF!
Name blankjuly: #REF!
Name cc: #REF!
Name ccc: #REF!
Name ChackDate: #REF!
Name cimlot: #REF!
Name coating: #REF!
Name Coating_Wt: #REF!
Name COIL: #REF!
Name CUS: #REF!
Name D: #REF!
Name data: #REF!
Name DATAFORAPR: #REF!
Name DATE: #REF!
Name DateC: #REF!
Name DD: #REF!
Name ddd: #REF!
Name DEFECT: #REF!
Name DEN: #REF!
Name DIE: #REF!
Name E: #REF!
Name eee: #REF!
Name F: #REF!
Name FBACK: #REF!
Name ff: #REF!
Name fff: #REF!
Name FG: #REF!
Name FGBLANK: #REF!
Name FGFORM: #REF!
Name first: #REF!
Name forcastaug: #REF!
Name fore: #REF!
Name forecast: #REF!
Name forecastjuli: #REF!
Name forecastold: #REF!
Name FORESEP: #REF!
Name FORM: #REF!
Name forme: #REF!
Name formjuly: #REF!
Name G: #REF!
Name ggg: #REF!

Sheet SA007 2025.01-2026.05 
A1: SECC-16/16_1.2_1219_CHINA STEEL | D1: RM600ST000027 | L1: 1 | M1: =L1+1 -> 2 | N1: =M1+1 -> 3 | O1: =N1+1 -> 4 | P1: =O1+1 -> 5 | Q1: =P1+1 -> 6 | R1: =Q1+1 -> 7 | S1: =R1+1 -> 8 | T1: =S1+1 -> 9 | ... W1: =V1+1 -> 12 | X1: 1 | Y1: =X1+1 -> 2 | Z1: =Y1+1 -> 3 | AC1: =W1+1 -> 13 | AG1: Copy สูตรใหม่ทุกครั้ง
L2: =SUBTOTAL(9,L5:L690) -> 289246.5 | M2: =SUBTOTAL(9,M5:M690) -> 272944 | N2: =SUBTOTAL(9,N5:N690) -> 293886.8 | O2: =SUBTOTAL(9,O5:O690) -> 266819.5 | P2: =SUBTOTAL(9,P5:P690) -> 321106 | Q2: =SUBTOTAL(9,Q5:Q690) -> 303203 | R2: =SUBTOTAL(9,R5:R690) -> 302654.1 | S2: =SUBTOTAL(9,S5:S690) -> 325115.04 | ... AB2: =SUBTOTAL(9,AB5:AB690) -> 253487 | AC2: =SUBTOTAL(9,AC5:AC396) -> 4040624.4 | AD2: =SUBTOTAL(9,AD5:AD1582) -> 335853.03 | AG2: SO-003 20.05.2026
A3: Material Code | B3: Material Spec | C3: PTT Spec | D3: FG Code | E3: Customer | F3: Delivery Place | G3: Mat Kind | H3: DO Mat Spec | I3: T | J3: W | K3: L | L3: 2025 | M3: 2025 | N3: 2025 | O3: 2025 | P3: 2025 | Q3: 2025 | R3: 2025 | S3: 2025 | T3: 2025 | U3: 2025 | V3: 2025 | W3: 2025 | X3: 2026 | Y3: 2026 | Z3: 2026 | AA3: 2026 | AB3: 2026 | AC3: Summary | AD3: Jan'25-Mar'2026 | AG3: Total PO (kg) | AH3: Delvered (kg) | AI3: Bal (kg)
L4: Jan | M4: Feb | N4: Mar | O4: Apr | P4: May | Q4: Jun | R4: July | S4: Aug | T4: Sep | U4: Oct | V4: Nov | W4: Dec | X4: Jan | Y4: Feb | Z4: Mar | AA4: Apr | AB4: May | AC4: Total | AD4: Avereage | AE4: Remark RD004
A5: SECD_0.5_1219_Common | B5: SECCD | C5: SECCD | D5: 101140 | E5: GINFONG | F5: GINFONG | G5: EG | H5: SECD | I5: 0.5 | J5: 55 | K5: COIL | L5: 0 | M5: 457 | N5: 1762 | O5: 0 | P5: 1012 | Q5: 7919 | R5: 3107 | S5: 0 | T5: 2323 | U5: 1158 | V5: 0 | W5: 0 | X5: 919 | Y5: 0 | Z5: 0 | AA5: =SUMIF([1]SA007!$C:$C,'SA007 2025.01-2026.05 '!$D5,[1]SA007!P:P) -> 0 | AB5: =SUMIF([1]SA007!$C:$C,'SA007 2025.01-2026.05 '!$D5,[1]SA007!Q:Q) -> 0 | AC5: =SUM(L5:AB5) -> 18657 | AD5: =AVERAGE(L5:AB5) -> 1097.4706 | AE5: ห่อพลาสติกใส ล้มวางพาเลทไม้_x000D_ รัดสายเขียว 2 เส้น ครีบคว่ำ ครีบหงาย แยกพาเลท_x000D_ ครีบคว่ำ ครีบหงาย แยกพาเลท FG ระบุพาเลทและคีบคว่ำหงายลง Remark ในระบบด้วย | AG5: =SUMIF([1]SO003!$H:$H,'SA007 2025.01-2026.05 '!$D5,[1]SO003!AF:AF) -> 0 | AH5: =SUMIF([1]SO003!$H:$H,'SA007 2025.01-2026.05 '!$D5,[1]SO003!AH:AH) -> 0 | AI5: =SUMIF([1]SO003!$H:$H,'SA007 2025.01-2026.05 '!$D5,[1]SO003!AJ:AJ) -> 0
A6: SPFH590-P/O_2_1219_Common | B6: SPFH590-P/O | C6: SPFH590-P/O | D6: 4168065 | E6: WISDOM AUTO | F6: WISDOM AUTO | G6: HR | H6: SPFH590-P/O | I6: 2 | J6: 220 | K6: 1220 | L6: 0 | M6: 0 | N6: 420 | O6: 0 | P6: 0 | Q6: 0 | R6: 0 | S6: 0 | T6: 0 | U6: 0 | V6: 0 | W6: 0 | X6: 0 | Y6: 0 | Z6: 0 | AA6: =SUMIF([1]SA007!$C:$C,'SA007 2025.01-2026.05 '!$D6,[1]SA007!P:P) -> 0 | AB6: =SUMIF([1]SA007!$C:$C,'SA007 2025.01-2026.05 '!$D6,[1]SA007!Q:Q) -> 0 | AC6: =SUM(L6:AB6) -> 420 | AD6: =AVERAGE(L6:AB6) -> 24.705882 | AE6: ห่อพลาสติกใส วางพาเลทไม้ | AG6: =SUMIF([1]SO003!$H:$H,'SA007 2025.01-2026.05 '!$D6,[1]SO003!AF:AF) -> 0 | AH6: =SUMIF([1]SO003!$H:$H,'SA007 2025.01-2026.05 '!$D6,[1]SO003!AH:AH) -> 0 | AI6: =SUMIF([1]SO003!$H:$H,'SA007 2025.01-2026.05 '!$D6,[1]SO003!AJ:AJ) -> 0
A7: SPFH590-P/O_2_1219_Common | B7: SPFH590-P/O | C7: SPFH590-P/O | D7: 4535289 | E7: WISDOM AUTO | F7: WISDOM AUTO | G7: HR | H7: SPFH590 P/O | I7: 2 | J7: 95 | K7: 1220 | L7: 0 | M7: 0 | N7: 183 | O7: 184 | P7: 0 | Q7: 0 | R7: 0 | S7: 0 | T7: 0 | U7: 0 | V7: 0 | W7: 0 | X7: 0 | Y7: 0 | Z7: 0 | AA7: =SUMIF([1]SA007!$C:$C,'SA007 2025.01-2026.05 '!$D7,[1]SA007!P:P) -> 0 | AB7: =SUMIF([1]SA007!$C:$C,'SA007 2025.01-2026.05 '!$D7,[1]SA007!Q:Q) -> 0 | AC7: =SUM(L7:AB7) -> 367 | AD7: =AVERAGE(L7:AB7) -> 21.588235 | AE7: ห่อพลาสติกใส วางพาเลทไม้ วาง 2 ตอน | AG7: =SUMIF([1]SO003!$H:$H,'SA007 2025.01-2026.05 '!$D7,[1]SO003!AF:AF) -> 0 | AH7: =SUMIF([1]SO003!$H:$H,'SA007 2025.01-2026.05 '!$D7,[1]SO003!AH:AH) -> 0 | AI7: =SUMIF([1]SO003!$H:$H,'SA007 2025.01-2026.05 '!$D7,[1]SO003!AJ:AJ) -> 0
A8: SPFH590-P/O_2_1219_Common | B8: SPFH590-P/O | C8: SPFH590-P/O | D8: 4671626 | E8: WISDOM AUTO | F8: WISDOM AUTO | G8: HR | H8: SPFH590-P/O | I8: 2 | J8: 220 | K8: 1220 | L8: 0 | M8: 0 | N8: 420 | O8: 907 | P8: 0 | Q8: 0 | R8: 0 | S8: 0 | T8: 0 | U8: 0 | V8: 0 | W8: 0 | X8: 0 | Y8: 0 | Z8: 0 | AA8: =SUMIF([1]SA007!$C:$C,'SA007 2025.01-2026.05 '!$D8,[1]SA007!P:P) -> 0 | AB8: =SUMIF([1]SA007!$C:$C,'SA007 2025.01-2026.05 '!$D8,[1]SA007!Q:Q) -> 0 | AC8: =SUM(L8:AB8) -> 1327 | AD8: =AVERAGE(L8:AB8) -> 78.058824 | AE8: ห่อพลาสติกใส วางพาเลทไม้ | AG8: =SUMIF([1]SO003!$H:$H,'SA007 2025.01-2026.05 '!$D8,[1]SO003!AF:AF) -> 0 | AH8: =SUMIF([1]SO003!$H:$H,'SA007 2025.01-2026.05 '!$D8,[1]SO003!AH:AH) -> 0 | AI8: =SUMIF([1]SO003!$H:$H,'SA007 2025.01-2026.05 '!$D8,[1]SO003!AJ:AJ) -> 0
A9: SGCC-Z22_0.5_1219_Common | B9: SGCC-Z22 | C9: SGCC-Z22 | D9: 0209000752 | E9: HONESTY | F9: HONESTY | G9: GI | H9: SGCC Z22 | I9: 0.5 | J9: 121.5 | K9: 1219 | L9: 0 | M9: 581 | N9: 0 | O9: 0 | P9: 0 | Q9: 0 | R9: 626 | S9: 0 | T9: 0 | U9: 0 | V9: 0 | W9: 0 | X9: 580 | Y9: 0 | Z9: 0 | AA9: =SUMIF([1]SA007!$C:$C,'SA007 2025.01-2026.05 '!$D9,[1]SA007!P:P) -> 0 | AB9: =SUMIF([1]SA007!$C:$C,'SA007 2025.01-2026.05 '!$D9,[1]SA007!Q:Q) -> 0 | AC9: =SUM(L9:AB9) -> 1787 | AD9: =AVERAGE(L9:AB9) -> 105.11765 | AE9: แนบ Cer. POSCO เท่านั้น ห่อพลาสติกใส แนบ INSPECTION DATA_x000D_ | AG9: =SUMIF([1]SO003!$H:$H,'SA007 2025.01-2026.05 '!$D9,[1]SO003!AF:AF) -> 0 | AH9: =SUMIF([1]SO003!$H:$H,'SA007 2025.01-2026.05 '!$D9,[1]SO003!AH:AH) -> 0 | AI9: =SUMIF([1]SO003!$H:$H,'SA007 2025.01-2026.05 '!$D9,[1]SO003!AJ:AJ) -> 0
A10: SPCC-SD_2.8_1219_Common | B10: SPCC-SD | C10: SPCC-SD | D10: 1010128001 | E10: GINFONG | F10: GINFONG | G10: CR | H10: SPCC | I10: 2.8 | J10: 140.5 | K10: COIL | L10: 2180 | M10: 2633 | N10: 0 | O10: 1017 | P10: 616 | Q10: 0 | R10: 0 | S10: 0 | T10: 0 | U10: 0 | V10: 0 | W10: 0 | X10: 0 | Y10: 0 | Z10: 1582 | AA10: =SUMIF([1]SA007!$C:$C,'SA007 2025.01-2026.05 '!$D10,[1]SA007!P:P) -> 1040 | AB10: =SUMIF([1]SA007!$C:$C,'SA007 2025.01-2026.05 '!$D10,[1]SA007!Q:Q) -> 0 | AC10: =SUM(L10:AB10) -> 9068 | AD10: =AVERAGE(L10:AB10) -> 533.41176 | AE10: เน้นผิวและคุณภาพ _x000D_ ห่อพลาสติกใส ล้มวางไม้พาเลท 1 แถบ/พาเลท_x000D_ ครีบคว่ำ ครีบหงาย แยกพาเลท FG ระบุพาเลทและคีบคว่ำหงายลง Remark ในระบบด้วย | AG10: =SUMIF([1]SO003!$H:$H,'SA007 2025.01-2026.05 '!$D10,[1]SO003!AF:AF) -> 0 | AH10: =SUMIF([1]SO003!$H:$H,'SA007 2025.01-2026.05 '!$D10,[1]SO003!AH:AH) -> 0 | AI10: =SUMIF([1]SO003!$H:$H,'SA007 2025.01-2026.05 '!$D10,[1]SO003!AJ:AJ) -> 0
A11: SGCC-Z22_0.8_1350_CHINA STEEL | B11: SGCC-Z18 | C11: SGCC-Z18 | D11: SGUR-0012-(65) | E11: UKKARIT | F11: UKKARIT | G11: GI | H11: GI/SGCC-Z18/Z22 | I11: 0.8 | J11: 320 | K11: 760 | L11: 0 | M11: 764 | N11: 743 | O11: 0 | P11: 0 | Q11: 744 | R11: 1492 | S11: 0 | T11: 1572 | U11: 0 | V11: 0 | W11: 0 | X11: 0 | Y11: 0 | Z11: 0 | AA11: =SUMIF([1]SA007!$C:$C,'SA007 2025.01-2026.05 '!$D11,[1]SA007!P:P) -> 0 | AB11: =SUMIF([1]SA007!$C:$C,'SA007 2025.01-2026.05 '!$D11,[1]SA007!Q:Q) -> 0 | AC11: =SUM(L11:AB11) -> 5315 | AD11: =AVERAGE(L11:AB11) -> 312.64706 | AE11: เน้นผิวและคุณภาพ_x000D_ ห่อพลาสติกใส วางไม้พาเลท วาง 3 แถว_x000D_ | AG11: =SUMIF([1]SO003!$H:$H,'SA007 2025.01-2026.05 '!$D11,[1]SO003!AF:AF) -> 0 | AH11: =SUMIF([1]SO003!$H:$H,'SA007 2025.01-2026.05 '!$D11,[1]SO003!AH:AH) -> 0 | AI11: =SUMIF([1]SO003!$H:$H,'SA007 2025.01-2026.05 '!$D11,[1]SO003!AJ:AJ) -> 0
A12: SGCC-Z27_1.5_1219_POSCO/BAO | B12: SGCC-Z18 | C12: SGCC-Z18 | D12: 1010415004 | E12: GINFONG | F12: GINFONG | G12: GI | H12: SGCC Z18 | I12: 1.5 | J12: 135.2 | K12: COIL | L12: 2805 | M12: 2140 | N12: 4058 | O12: 1351 | P12: 0 | Q12: 1962 | R12: 1383 | S12: 1152 | T12: 4994 | U12: 4018 | V12: 0 | W12: 1965 | X12: 674 | Y12: 0 | Z12: 0 | AA12: =SUMIF([1]SA007!$C:$C,'SA007 2025.01-2026.05 '!$D12,[1]SA007!P:P) -> 2272 | AB12: =SUMIF([1]SA007!$C:$C,'SA007 2025.01-2026.05 '!$D12,[1]SA007!Q:Q) -> 3245 | AC12: =SUM(L12:AB12) -> 32019 | AD12: =AVERAGE(L12:AB12) -> 1883.4706 | AE12: ห่อพลาสติกใส ล้มวางไม้พาเลท 1 แถบ/พาเลท ครีบคว่ำ ครีบหงาย FG ระบุพาเลทและคีบคว่ำหงายลง Remark ในระบบด้วย ลูกค้าเน้นสีผิวแมทห้ามมีสีต่างกัน_x000D_ INSPECTION DATA_x000D_ | AG12: =SUMIF([1]SO003!$H:$H,'SA007 2025.01-2026.05 '!$D12,[1]SO003!AF:AF) -> 7200 | AH12: =SUMIF([1]SO003!$H:$H,'SA007 2025.01-2026.05 '!$D12,[1]SO003!AH:AH) -> 2547 | AI12: =SUMIF([1]SO003!$H:$H,'SA007 2025.01-2026.05 '!$D12,[1]SO003!AJ:AJ) -> 1553
A13: SECC-16/16_0.8_1219_Common | B13: SECC-16/16 | C13: SECC | D13: 1010508003 | E13: GINFONG | F13: GINFONG | G13: EG | H13: SECC | I13: 0.8 | J13: 68 | K13: COIL | L13: 0 | M13: 1606 | N13: 0 | O13: 1846 | P13: 0 | Q13: 1822 | R13: 1129 | S13: 0 | T13: 2635 | U13: 1485 | V13: 966 | W13: 1303 | X13: 555 | Y13: 0 | Z13: 3250 | AA13: =SUMIF([1]SA007!$C:$C,'SA007 2025.01-2026.05 '!$D13,[1]SA007!P:P) -> 0 | AB13: =SUMIF([1]SA007!$C:$C,'SA007 2025.01-2026.05 '!$D13,[1]SA007!Q:Q) -> 0 | AC13: =SUM(L13:AB13) -> 16597 | AD13: =AVERAGE(L13:AB13) -> 976.29412 | AE13: ลูกค้าเน้น ห้ามมีรอย Roller Mark รัดสายเขียว 2 เส้น ครีบคว่ำ ครีบหงาย แยกพาเลท ไม้คั่น 40 mm._x000D_ ครีบคว่ำ ครีบหงาย แยกพาเลท FG ระบุพาเลทและคีบคว่ำหงายลง Remark ในระบบด้วย | AG13: =SUMIF([1]SO003!$H:$H,'SA007 2025.01-2026.05 '!$D13,[1]SO003!AF:AF) -> 1000 | AH13: =SUMIF([1]SO003!$H:$H,'SA007 2025.01-2026.05 '!$D13,[1]SO003!AH:AH) -> 0 | AI13: =SUMIF([1]SO003!$H:$H,'SA007 2025.01-2026.05 '!$D13,[1]SO003!AJ:AJ) -> 1000
A14: SECC-E16/E16_1_1180_Common | B14: SECC-16/16 | C14: SECC | D14: 1010510009 | E14: GINFONG | F14: GINFONG | G14: EG | H14: SECC | I14: 1 | J14: 124 | K14: COIL | L14: 5384 | M14: 12258 | N14: 0 | O14: 4241 | P14: 10960 | Q14: 5491 | R14: 7016.5 | S14: 12001 | T14: 0 | U14: 765 | V14: 3500 | W14: 0 | X14: 1621 | Y14: 0 | Z14: 0 | AA14: =SUMIF([1]SA007!$C:$C,'SA007 2025.01-2026.05 '!$D14,[1]SA007!P:P) -> 0 | AB14: =SUMIF([1]SA007!$C:$C,'SA007 2025.01-2026.05 '!$D14,[1]SA007!Q:Q) -> 0 | AC14: =SUM(L14:AB14) -> 63237.5 | AD14: =AVERAGE(L14:AB14) -> 3719.8529 | AE14: ลูกค้าไม่ยอมรับรอย Roller Mark, ห่อพลาสติกใส ล้มวางไม้พาเลท 2 แถบ/พาเลท ** มีไม้คั่น ** ครีบคว่ำ ครีบหงาย แยกพาเลท FG ระบุพาเลทและคีบคว่ำหงายลง Remark ในระบบด้วย_x000D_ แนบ INSPECTION DATA | AG14: =SUMIF([1]SO003!$H:$H,'SA007 2025.01-2026.05 '!$D14,[1]SO003!AF:AF) -> 0 | AH14: =SUMIF([1]SO003!$H:$H,'SA007 2025.01-2026.05 '!$D14,[1]SO003!AH:AH) -> 0 | AI14: =SUMIF([1]SO003!$H:$H,'SA007 2025.01-2026.05 '!$D14,[1]SO003!AJ:AJ) -> 0
A15: SECD_0.5_1219_Common | B15: SECCD | C15: SECCD | D15: 1011405004 | E15: GINFONG | F15: GINFONG | G15: EG | H15: SECD | I15: 0.5 | J15: 179 | K15: COIL | L15: 1866 | M15: 3555 | N15: 1654 | O15: 2177 | P15: 0 | Q15: 0 | R15: 0 | S15: 0 | T15: 1112 | U15: 1033 | V15: 1442 | W15: 0 | X15: 1101 | Y15: 0 | Z15: 1587 | AA15: =SUMIF([1]SA007!$C:$C,'SA007 2025.01-2026.05 '!$D15,[1]SA007!P:P) -> 411 | AB15: =SUMIF([1]SA007!$C:$C,'SA007 2025.01-2026.05 '!$D15,[1]SA007!Q:Q) -> 1528 | AC15: =SUM(L15:AB15) -> 17466 | AD15: =AVERAGE(L15:AB15) -> 1027.4118 | AE15: เน้นผิวและคุณภาพ, ห่อพลาสติกใส ล้มวางไม้พาเลท 1 แถบ/พาเลท_x000D_ ลูกค้ายอมรับรอย Roller mark ได้ให้รอยอยู่ด้านในของม้วน Maker BAO/CSC น้ำหนัก 1,000 kg./Pallat น้ำหนัก 400-600 kg./Coil แนบ INSPECTION_x000D__x000D_ ครีบคว่ำ ครีบหงาย แยกพาเลท | AG15: =SUMIF([1]SO003!$H:$H,'SA007 2025.01-2026.05 '!$D15,[1]SO003!AF:AF) -> 500 | AH15: =SUMIF([1]SO003!$H:$H,'SA007 2025.01-2026.05 '!$D15,[1]SO003!AH:AH) -> 0 | AI15: =SUMIF([1]SO003!$H:$H,'SA007 2025.01-2026.05 '!$D15,[1]SO003!AJ:AJ) -> 500
A16: SGCC-Z22_0.8_1350_CHINA STEEL | B16: SGCC-Z18 | C16: SGCC-Z18 | D16: SGUR-0012-(66) | E16: UKKARIT | F16: UKKARIT | G16: GI | H16: GI/SGCC-Z18/Z22 | I16: 0.8 | J16: 320 | K16: 1060 | L16: 0 | M16: 1064 | N16: 2042 | O16: 0 | P16: 0 | Q16: 1040 | R16: 2076 | S16: 2544 | T16: 2054 | U16: 0 | V16: 0 | W16: 0 | X16: 0 | Y16: 0 | Z16: 0 | AA16: =SUMIF([1]SA007!$C:$C,'SA007 2025.01-2026.05 '!$D16,[1]SA007!P:P) -> 0 | AB16: =SUMIF([1]SA007!$C:$C,'SA007 2025.01-2026.05 '!$D16,[1]SA007!Q:Q) -> 0 | AC16: =SUM(L16:AB16) -> 10820 | AD16: =AVERAGE(L16:AB16) -> 636.47059 | AE16: เน้นผิวและคุณภาพ ห่อพลาสติกใส วางไม้พาเลท วาง 1 แถว_x000D_ แนบ INSPECTION_x000D_ | AG16: =SUMIF([1]SO003!$H:$H,'SA007 2025.01-2026.05 '!$D16,[1]SO003!AF:AF) -> 0 | AH16: =SUMIF([1]SO003!$H:$H,'SA007 2025.01-2026.05 '!$D16,[1]SO003!AH:AH) -> 0 | AI16: =SUMIF([1]SO003!$H:$H,'SA007 2025.01-2026.05 '!$D16,[1]SO003!AJ:AJ) -> 0
A17: SPCC-SD_0.4_1219_Common | B17: SPCC-SD | C17: SPCC-SD | D17: 0.400X90.00XCOIL | E17: SHENGTAI | F17: SHENGTAI | G17: CR | H17: SPCC | I17: 0.4 | J17: 90 | K17: COIL | L17: 0 | M17: 1325 | N17: 0 | O17: 831 | P17: 1080 | Q17: 798 | R17: 1624 | S17: 0 | T17: 0 | U17: 960 | V17: 0 | W17: 1076 | X17: 1329 | Y17: 0 | Z17: 624 | AA17: =SUMIF([1]SA007!$C:$C,'SA007 2025.01-2026.05 '!$D17,[1]SA007!P:P) -> 624 | AB17: =SUMIF([1]SA007!$C:$C,'SA007 2025.01-2026.05 '!$D17,[1]SA007!Q:Q) -> 0 | AC17: =SUM(L17:AB17) -> 10271 | AD17: =AVERAGE(L17:AB17) -> 604.17647 | AE17: ห่อพลาสติกใส ล้มวางไม้พาเลท แนบ INSPECTION DATA_x000D_ | AG17: =SUMIF([1]SO003!$H:$H,'SA007 2025.01-2026.05 '!$D17,[1]SO003!AF:AF) -> 0 | AH17: =SUMIF([1]SO003!$H:$H,'SA007 2025.01-2026.05 '!$D17,[1]SO003!AH:AH) -> 0 | AI17: =SUMIF([1]SO003!$H:$H,'SA007 2025.01-2026.05 '!$D17,[1]SO003!AJ:AJ) -> 0
A18: SPCC-SD_0.4_1219_Common | B18: SPCC-SD | C18: SPCC-SD | D18: 0.4X116XCOIL | E18: SHENGTAI | F18: SHENGTAI | G18: CR | H18: SPCC | I18: 0.4 | J18: 116 | K18: COIL | L18: 0 | M18: 295 | N18: 0 | O18: 290 | P18: 1473 | Q18: 1028 | R18: 0 | S18: 0 | T18: 0 | U18: 0 | V18: 2060 | W18: 0 | X18: 0 | Y18: 0 | Z18: 1342 | AA18: =SUMIF([1]SA007!$C:$C,'SA007 2025.01-2026.05 '!$D18,[1]SA007!P:P) -> 0 | AB18: =SUMIF([1]SA007!$C:$C,'SA007 2025.01-2026.05 '!$D18,[1]SA007!Q:Q) -> 0 | AC18: =SUM(L18:AB18) -> 6488 | AD18: =AVERAGE(L18:AB18) -> 381.64706 | AE18: WEIGHT MAX 1,000 KG._x000D_ ห่อพลาสติกใส ล้มวางพาเลทไม้ | AG18: =SUMIF([1]SO003!$H:$H,'SA007 2025.01-2026.05 '!$D18,[1]SO003!AF:AF) -> 0 | AH18: =SUMIF([1]SO003!$H:$H,'SA007 2025.01-2026.05 '!$D18,[1]SO003!AH:AH) -> 0 | AI18: =SUMIF([1]SO003!$H:$H,'SA007 2025.01-2026.05 '!$D18,[1]SO003!AJ:AJ) -> 0
A19: SPCC-SD_0.4_1219_Common | B19: SPCC-SD | C19: SPCC-SD | D19: 0.4X130.5XCOIL | E19: SHENGTAI | F19: SHENGTAI | G19: CR | H19: SPCC | I19: 0.4 | J19: 130.5 | K19: COIL | L19: 0 | M19: 2724 | N19: 2765 | O19: 0 | P19: 4544 | Q19: 0 | R19: 2112 | S19: 3482 | T19: 0 | U19: 3140 | V19: 2310 | W19: 0 | X19: 3351 | Y19: 1711 | Z19: 0 | AA19: =SUMIF([1]SA007!$C:$C,'SA007 2025.01-2026.05 '!$D19,[1]SA007!P:P) -> 1298 | AB19: =SUMIF([1]SA007!$C:$C,'SA007 2025.01-2026.05 '!$D19,[1]SA007!Q:Q) -> 0 | AC19: =SUM(L19:AB19) -> 27437 | AD19: =AVERAGE(L19:AB19) -> 1613.9412 | AE19: ห่อพลาสติกใส ล้มวางไม้พาเลท แนบ INSPECTION DATA_x000D_ | AG19: =SUMIF([1]SO003!$H:$H,'SA007 2025.01-2026.05 '!$D19,[1]SO003!AF:AF) -> 0 | AH19: =SUMIF([1]SO003!$H:$H,'SA007 2025.01-2026.05 '!$D19,[1]SO003!AH:AH) -> 0 | AI19: =SUMIF([1]SO003!$H:$H,'SA007 2025.01-2026.05 '!$D19,[1]SO003!AJ:AJ) -> 0
A20: SPCC-SD_0.5_1219_Common | B20: SPCC-SD | C20: SPCC-SD | D20: 0.500X27.00XCOIL | E20: MING TAI | F20: MING TAI | G20: CR | H20: SPCC-SD | I20: 0.5 | J20: 27 | K20: C | L20: 73 | M20: 0 | N20: 0 | O20: 0 | P20: 0 | Q20: 0 | R20: 0 | S20: 0 | T20: 0 | U20: 0 | V20: 0 | W20: 0 | X20: 0 | Y20: 0 | Z20: 0 | AA20: =SUMIF([1]SA007!$C:$C,'SA007 2025.01-2026.05 '!$D20,[1]SA007!P:P) -> 0 | AB20: =SUMIF([1]SA007!$C:$C,'SA007 2025.01-2026.05 '!$D20,[1]SA007!Q:Q) -> 0 | AC20: =SUM(L20:AB20) -> 73 | AD20: =AVERAGE(L20:AB20) -> 4.2941176 | AE20: EYE UP. | AG20: =SUMIF([1]SO003!$H:$H,'SA007 2025.01-2026.05 '!$D20,[1]SO003!AF:AF) -> 0 | AH20: =SUMIF([1]SO003!$H:$H,'SA007 2025.01-2026.05 '!$D20,[1]SO003!AH:AH) -> 0 | AI20: =SUMIF([1]SO003!$H:$H,'SA007 2025.01-2026.05 '!$D20,[1]SO003!AJ:AJ) -> 0
A21: SECC-16/16_0.5_1219_Common | B21: SECC-16/16 | C21: SECC | D21: 0.500X70.00XCOIL | E21: FEITI | F21: FEITI | G21: EG | H21: SECC | I21: 0.5 | J21: 70 | K21: COIL | L21: 0 | M21: 0 | N21: 195 | O21: 0 | P21: 504 | Q21: 0 | R21: 0 | S21: 0 | T21: 0 | U21: 0 | V21: 0 | W21: 0 | X21: 0 | Y21: 0 | Z21: 0 | AA21: =SUMIF([1]SA007!$C:$C,'SA007 2025.01-2026.05 '!$D21,[1]SA007!P:P) -> 0 | AB21: =SUMIF([1]SA007!$C:$C,'SA007 2025.01-2026.05 '!$D21,[1]SA007!Q:Q) -> 0 | AC21: =SUM(L21:AB21) -> 699 | AD21: =AVERAGE(L21:AB21) -> 41.117647 | AE21: เน้นผิวและคุณภาพ_x000D_ น้ำหนัก 500-1000 กก. ห่อพลาสติกใส ล้มวางไม้ 3 แถบ/พาเลท มีไม้คั่น_x000D_ ลูกค้ายอมรับรอย Roller mark ได้ | AG21: =SUMIF([1]SO003!$H:$H,'SA007 2025.01-2026.05 '!$D21,[1]SO003!AF:AF) -> 0 | AH21: =SUMIF([1]SO003!$H:$H,'SA007 2025.01-2026.05 '!$D21,[1]SO003!AH:AH) -> 0 | AI21: =SUMIF([1]SO003!$H:$H,'SA007 2025.01-2026.05 '!$D21,[1]SO003!AJ:AJ) -> 0
A22: SGCD1-Z08_0.5_1219_Common | B22: SGCD | C22: SGCD | D22: 0.50X170.00XCOIL | E22: GINFONG | F22: GINFONG | G22: GI | H22: SGCD | I22: 0.5 | J22: 170 | K22: COIL | L22: 1486 | M22: 2648 | N22: 2269.3 | O22: 1484 | P22: 0 | Q22: 0 | R22: 966 | S22: 0 | T22: 1083 | U22: 1070 | V22: 1591 | W22: 0 | X22: 2238 | Y22: 0 | Z22: 1361 | AA22: =SUMIF([1]SA007!$C:$C,'SA007 2025.01-2026.05 '!$D22,[1]SA007!P:P) -> 0 | AB22: =SUMIF([1]SA007!$C:$C,'SA007 2025.01-2026.05 '!$D22,[1]SA007!Q:Q) -> 1050 | AC22: =SUM(L22:AB22) -> 17246.3 | AD22: =AVERAGE(L22:AB22) -> 1014.4882 | AE22: QC เช็คผิวเหล็กก่อนทำการตัด_x000D_ ลูกค้าเน้นสีผิวเหล็ก ไม่มีลายตามตัวอย่าง Approve วันที่ 02/03/2023 เช็คผิวเหล็กจริงได้ที่ห้องคิวซี คุณภควัต_x000D_ ใช้ Maker BAO/CSC/POSCO_x000D_ น้ำหนัก 1,000 kg./Palat น้ำหนัก 400-800 kg./Coil_x000D_ น้ำหนักตามชั่งจริง_x000D_ ครีบคว่ำ ครีบหงาย | AG22: =SUMIF([1]SO003!$H:$H,'SA007 2025.01-2026.05 '!$D22,[1]SO003!AF:AF) -> 0 | AH22: =SUMIF([1]SO003!$H:$H,'SA007 2025.01-2026.05 '!$D22,[1]SO003!AH:AH) -> 0 | AI22: =SUMIF([1]SO003!$H:$H,'SA007 2025.01-2026.05 '!$D22,[1]SO003!AJ:AJ) -> 0
A23: SPCC-SD_0.5_1219_Common | B23: SPCC-SD | C23: SPCC-SD | D23: 0.50x370x600 | E23: SAN HO PRECISION | F23: SAN HO PRECISION | G23: CR | H23: SPCC | I23: 0.5 | J23: 370 | K23: 600 | L23: 0 | M23: 0 | N23: 107 | O23: 0 | P23: 0 | Q23: 0 | R23: 0 | S23: 0 | T23: 0 | U23: 0 | V23: 0 | W23: 0 | X23: 0 | Y23: 0 | Z23: 0 | AA23: =SUMIF([1]SA007!$C:$C,'SA007 2025.01-2026.05 '!$D23,[1]SA007!P:P) -> 0 | AB23: =SUMIF([1]SA007!$C:$C,'SA007 2025.01-2026.05 '!$D23,[1]SA007!Q:Q) -> 0 | AC23: =SUM(L23:AB23) -> 107 | AD23: =AVERAGE(L23:AB23) -> 6.2941176 | AG23: =SUMIF([1]SO003!$H:$H,'SA007 2025.01-2026.05 '!$D23,[1]SO003!AF:AF) -> 0 | AH23: =SUMIF([1]SO003!$H:$H,'SA007 2025.01-2026.05 '!$D23,[1]SO003!AH:AH) -> 0 | AI23: =SUMIF([1]SO003!$H:$H,'SA007 2025.01-2026.05 '!$D23,[1]SO003!AJ:AJ) -> 0
A24: SPCC-SD_0.5_1219_Common | B24: SPCC-SD | C24: SPCC-SD | D24: 0.50x488X610 | E24: SAN HO PRECISION | F24: SAN HO PRECISION | G24: CR | H24: SPCC | I24: 0.5 | J24: 488 | K24: 610 | L24: 0 | M24: 1223 | N24: 3067 | O24: 0 | P24: 0 | Q24: 0 | R24: 0 | S24: 0 | T24: 0 | U24: 0 | V24: 0 | W24: 956 | X24: 0 | Y24: 0 | Z24: 0 | AA24: =SUMIF([1]SA007!$C:$C,'SA007 2025.01-2026.05 '!$D24,[1]SA007!P:P) -> 813 | AB24: =SUMIF([1]SA007!$C:$C,'SA007 2025.01-2026.05 '!$D24,[1]SA007!Q:Q) -> 0 | AC24: =SUM(L24:AB24) -> 6059 | AD24: =AVERAGE(L24:AB24) -> 356.41176 | AG24: =SUMIF([1]SO003!$H:$H,'SA007 2025.01-2026.05 '!$D24,[1]SO003!AF:AF) -> 1448.8086 | AH24: =SUMIF([1]SO003!$H:$H,'SA007 2025.01-2026.05 '!$D24,[1]SO003!AH:AH) -> 1369.3578 | AI24: =SUMIF([1]SO003!$H:$H,'SA007 2025.01-2026.05 '!$D24,[1]SO003!AJ:AJ) -> 79.450792
A25: SECC-16/16_0.5_1219_Common | B25: SECC-16/16 | C25: SECC | D25: 0.5x163xCoil | E25: XINGGAOSHENG | F25: XINGGAOSHENG | G25: EG | H25: SECC | I25: 0.5 | J25: 163 | K25: COIL | L25: 0 | M25: 0 | N25: 0 | O25: 0 | P25: 0 | Q25: 0 | R25: 0 | S25: 0 | T25: 0 | U25: 0 | V25: 0 | W25: 0 | X25: 0 | Y25: 0 | Z25: 0 | AA25: =SUMIF([1]SA007!$C:$C,'SA007 2025.01-2026.05 '!$D25,[1]SA007!P:P) -> 0 | AB25: =SUMIF([1]SA007!$C:$C,'SA007 2025.01-2026.05 '!$D25,[1]SA007!Q:Q) -> 0 | AC25: =SUM(L25:AB25) -> 0 | AD25: =AVERAGE(L25:AB25) -> 0 | AG25: =SUMIF([1]SO003!$H:$H,'SA007 2025.01-2026.05 '!$D25,[1]SO003!AF:AF) -> 0 | AH25: =SUMIF([1]SO003!$H:$H,'SA007 2025.01-2026.05 '!$D25,[1]SO003!AH:AH) -> 0 | AI25: =SUMIF([1]SO003!$H:$H,'SA007 2025.01-2026.05 '!$D25,[1]SO003!AJ:AJ) -> 0
A26: SGCC-Z22_0.8_1350_CHINA STEEL | B26: SGCC-Z18 | C26: SGCC-Z18 | D26: SGUR-0012-(67) | E26: UKKARIT | F26: UKKARIT | G26: GI | H26: GI/SGCC-Z18/Z22 | I26: 0.8 | J26: 320 | K26: 1460 | L26: 0 | M26: 1459 | N26: 2824 | O26: 0 | P26: 0 | Q26: 2912 | R26: 0 | S26: 2920 | T26: 2802 | U26: 0 | V26: 0 | W26: 0 | X26: 0 | Y26: 0 | Z26: 0 | AA26: =SUMIF([1]SA007!$C:$C,'SA007 2025.01-2026.05 '!$D26,[1]SA007!P:P) -> 0 | AB26: =SUMIF([1]SA007!$C:$C,'SA007 2025.01-2026.05 '!$D26,[1]SA007!Q:Q) -> 0 | AC26: =SUM(L26:AB26) -> 12917 | AD26: =AVERAGE(L26:AB26) -> 759.82353 | AE26: เน้นผิวและคุณภาพ ห่อพลาสติกใส วางไม้พาเลท วาง 1 แถว_x000D_ แนบ INSPECTION_x000D_ | AG26: =SUMIF([1]SO003!$H:$H,'SA007 2025.01-2026.05 '!$D26,[1]SO003!AF:AF) -> 0 | AH26: =SUMIF([1]SO003!$H:$H,'SA007 2025.01-2026.05 '!$D26,[1]SO003!AH:AH) -> 0 | AI26: =SUMIF([1]SO003!$H:$H,'SA007 2025.01-2026.05 '!$D26,[1]SO003!AJ:AJ) -> 0
A27: SPCC-SD_0.5_1219_Common | B27: SPCC-SD | C27: SPCC-SD | D27: 0.5x200xCoil | E27: SAN HO PRECISION | F27: SAN HO PRECISION | G27: CR | H27: SPCC | I27: 0.5 | J27: 200 | K27: C | L27: 0 | M27: 0 | N27: 1062 | O27: 0 | P27: 0 | Q27: 0 | R27: 0 | S27: 0 | T27: 0 | U27: 2418 | V27: 0 | W27: 0 | X27: 0 | Y27: 0 | Z27: 0 | AA27: =SUMIF([1]SA007!$C:$C,'SA007 2025.01-2026.05 '!$D27,[1]SA007!P:P) -> 0 | AB27: =SUMIF([1]SA007!$C:$C,'SA007 2025.01-2026.05 '!$D27,[1]SA007!Q:Q) -> 0 | AC27: =SUM(L27:AB27) -> 3480 | AD27: =AVERAGE(L27:AB27) -> 204.70588 | AE27: SCRAP OVER 10mm RETURN CUSTOMER! | AG27: =SUMIF([1]SO003!$H:$H,'SA007 2025.01-2026.05 '!$D27,[1]SO003!AF:AF) -> 0 | AH27: =SUMIF([1]SO003!$H:$H,'SA007 2025.01-2026.05 '!$D27,[1]SO003!AH:AH) -> 0 | AI27: =SUMIF([1]SO003!$H:$H,'SA007 2025.01-2026.05 '!$D27,[1]SO003!AJ:AJ) -> 0
A28: SGCC-Z22_0.8_1350_CHINA STEEL | B28: SGCC-Z18 | C28: SGCC-Z18 | D28: SGUR-0012-(74) | E28: UKKARIT | F28: UKKARIT | G28: GI | H28: GI/SGCC-Z18/Z22 | I28: 0.8 | J28: 102.8 | K28: 738.8 | L28: 953 | M28: 951 | N28: 922 | O28: 0 | P28: 705 | Q28: 0 | R28: 0 | S28: 1165 | T28: 0 | U28: 460 | V28: 1392 | W28: 0 | X28: 0 | Y28: 0 | Z28: 0 | AA28: =SUMIF([1]SA007!$C:$C,'SA007 2025.01-2026.05 '!$D28,[1]SA007!P:P) -> 0 | AB28: =SUMIF([1]SA007!$C:$C,'SA007 2025.01-2026.05 '!$D28,[1]SA007!Q:Q) -> 0 | AC28: =SUM(L28:AB28) -> 6548 | AD28: =AVERAGE(L28:AB28) -> 385.17647 | AE28: เน้นผิวและคุณภาพ_x000D_ ห่อพลาสติกใส วางไม้พาเลท วาง 3 แถว_x000D_ | AG28: =SUMIF([1]SO003!$H:$H,'SA007 2025.01-2026.05 '!$D28,[1]SO003!AF:AF) -> 0 | AH28: =SUMIF([1]SO003!$H:$H,'SA007 2025.01-2026.05 '!$D28,[1]SO003!AH:AH) -> 0 | AI28: =SUMIF([1]SO003!$H:$H,'SA007 2025.01-2026.05 '!$D28,[1]SO003!AJ:AJ) -> 0
A29: SECC-16/16_0.5_1219_Common | B29: SECC-16/16 | C29: SECC | D29: 0.5x472xCoil | E29: XINGGAOSHENG | F29: XINGGAOSHENG | G29: EG | H29: SECC | I29: 0.5 | J29: 472 | K29: COIL | L29: 0 | M29: 0 | N29: 0 | O29: 0 | P29: 0 | Q29: 0 | R29: 0 | S29: 0 | T29: 0 | U29: 0 | V29: 0 | W29: 0 | X29: 0 | Y29: 0 | Z29: 0 | AA29: =SUMIF([1]SA007!$C:$C,'SA007 2025.01-2026.05 '!$D29,[1]SA007!P:P) -> 0 | AB29: =SUMIF([1]SA007!$C:$C,'SA007 2025.01-2026.05 '!$D29,[1]SA007!Q:Q) -> 0 | AC29: =SUM(L29:AB29) -> 0 | AD29: =AVERAGE(L29:AB29) -> 0 | AG29: =SUMIF([1]SO003!$H:$H,'SA007 2025.01-2026.05 '!$D29,[1]SO003!AF:AF) -> 0 | AH29: =SUMIF([1]SO003!$H:$H,'SA007 2025.01-2026.05 '!$D29,[1]SO003!AH:AH) -> 0 | AI29: =SUMIF([1]SO003!$H:$H,'SA007 2025.01-2026.05 '!$D29,[1]SO003!AJ:AJ) -> 0
A30: SECC-16/16_0.5_1219_Common | B30: SECC-16/16 | C30: SECC | D30: 0.5x67xCoil | E30: XINGGAOSHENG | F30: XINGGAOSHENG | G30: EG | H30: SECC | I30: 0.5 | J30: 67 | K30: COIL | L30: 0 | M30: 0 | N30: 0 | O30: 0 | P30: 0 | Q30: 0 | R30: 0 | S30: 0 | T30: 0 | U30: 0 | V30: 0 | W30: 0 | X30: 0 | Y30: 0 | Z30: 0 | AA30: =SUMIF([1]SA007!$C:$C,'SA007 2025.01-2026.05 '!$D30,[1]SA007!P:P) -> 0 | AB30: =SUMIF([1]SA007!$C:$C,'SA007 2025.01-2026.05 '!$D30,[1]SA007!Q:Q) -> 0 | AC30: =SUM(L30:AB30) -> 0 | AD30: =AVERAGE(L30:AB30) -> 0 | AG30: =SUMIF([1]SO003!$H:$H,'SA007 2025.01-2026.05 '!$D30,[1]SO003!AF:AF) -> 0 | AH30: =SUMIF([1]SO003!$H:$H,'SA007 2025.01-2026.05 '!$D30,[1]SO003!AH:AH) -> 0 | AI30: =SUMIF([1]SO003!$H:$H,'SA007 2025.01-2026.05 '!$D30,[1]SO003!AJ:AJ) -> 0
A31: SPCC-SD_0.6_1219_Common | B31: SPCC-SD | C31: SPCC-SD | D31: 0.60x500x1000 | E31: SAN HO PRECISION | F31: SAN HO PRECISION | G31: CR | H31: SPCC | I31: 0.6 | J31: 500 | K31: 1000 | L31: 2155 | M31: 0 | N31: 0 | O31: 0 | P31: 0 | Q31: 0 | R31: 0 | S31: 0 | T31: 0 | U31: 0 | V31: 0 | W31: 0 | X31: 0 | Y31: 0 | Z31: 0 | AA31: =SUMIF([1]SA007!$C:$C,'SA007 2025.01-2026.05 '!$D31,[1]SA007!P:P) -> 0 | AB31: =SUMIF([1]SA007!$C:$C,'SA007 2025.01-2026.05 '!$D31,[1]SA007!Q:Q) -> 0 | AC31: =SUM(L31:AB31) -> 2155 | AD31: =AVERAGE(L31:AB31) -> 126.76471 | AG31: =SUMIF([1]SO003!$H:$H,'SA007 2025.01-2026.05 '!$D31,[1]SO003!AF:AF) -> 0 | AH31: =SUMIF([1]SO003!$H:$H,'SA007 2025.01-2026.05 '!$D31,[1]SO003!AH:AH) -> 0 | AI31: =SUMIF([1]SO003!$H:$H,'SA007 2025.01-2026.05 '!$D31,[1]SO003!AJ:AJ) -> 0
A32: SPCC-SD_0.6_1219_Common | B32: SPCC-SD | C32: SPCC-SD | D32: 0.60x55.00xCOIL | E32: DIAMOND SAT | F32: DIAMOND SAT | G32: CR | H32: SPCC | I32: 0.6 | J32: 55 | K32: COIL | L32: 0 | M32: 152 | N32: 0 | O32: 0 | P32: 0 | Q32: 130 | R32: 0 | S32: 0 | T32: 0 | U32: 0 | V32: 0 | W32: 0 | X32: 0 | Y32: 0 | Z32: 0 | AA32: =SUMIF([1]SA007!$C:$C,'SA007 2025.01-2026.05 '!$D32,[1]SA007!P:P) -> 0 | AB32: =SUMIF([1]SA007!$C:$C,'SA007 2025.01-2026.05 '!$D32,[1]SA007!Q:Q) -> 0 | AC32: =SUM(L32:AB32) -> 282 | AD32: =AVERAGE(L32:AB32) -> 16.588235 | AE32: น้ำหนักตัดจริงห้ามเกิน PO หรือต้องไม่เกินน้ำหนักในใบแพลนระบุ ***เน้นย้ำห้ามเกินใบแพลนระบุ*** ห่อพลาสติกใส ล้มวางไม้พาเลท 1 แถบ/พาเลท_x000D_ แนบ INSPECTION DATA_x000D_ | AG32: =SUMIF([1]SO003!$H:$H,'SA007 2025.01-2026.05 '!$D32,[1]SO003!AF:AF) -> 0 | AH32: =SUMIF([1]SO003!$H:$H,'SA007 2025.01-2026.05 '!$D32,[1]SO003!AH:AH) -> 0 | AI32: =SUMIF([1]SO003!$H:$H,'SA007 2025.01-2026.05 '!$D32,[1]SO003!AJ:AJ) -> 0
A33: SECC-16/16_0.6_1219_Common | B33: SECC-16/16 | C33: SECC | D33: 0.6x133xCoil | E33: FEITI | F33: FEITI | G33: EG | H33: SECC | I33: 0.6 | J33: 133 | K33: COIL | L33: 0 | M33: 426 | N33: 830 | O33: 0 | P33: 0 | Q33: 0 | R33: 750 | S33: 822 | T33: 0 | U33: 0 | V33: 0 | W33: 0 | X33: 0 | Y33: 0 | Z33: 0 | AA33: =SUMIF([1]SA007!$C:$C,'SA007 2025.01-2026.05 '!$D33,[1]SA007!P:P) -> 0 | AB33: =SUMIF([1]SA007!$C:$C,'SA007 2025.01-2026.05 '!$D33,[1]SA007!Q:Q) -> 0 | AC33: =SUM(L33:AB33) -> 2828 | AD33: =AVERAGE(L33:AB33) -> 166.35294 | AE33: 0.6X133XCOIL ห่อพลาสติกใส ล้มวางไม้พาเลท 3 แถบ/พาเลท มีไม้คั่น_x000D_ แนบ INSPECTION_x000D_ | AG33: =SUMIF([1]SO003!$H:$H,'SA007 2025.01-2026.05 '!$D33,[1]SO003!AF:AF) -> 0 | AH33: =SUMIF([1]SO003!$H:$H,'SA007 2025.01-2026.05 '!$D33,[1]SO003!AH:AH) -> 0 | AI33: =SUMIF([1]SO003!$H:$H,'SA007 2025.01-2026.05 '!$D33,[1]SO003!AJ:AJ) -> 0
A34: SECC-16/16_0.6_1219_Common | B34: SECC-16/16 | C34: SECC | D34: 0.6x155xCoil | E34: FEITI | F34: FEITI | G34: EG | H34: SECC | I34: 0.6 | J34: 155 | K34: COIL | L34: 0 | M34: 1491 | N34: 1452 | O34: 0 | P34: 0 | Q34: 0 | R34: 828 | S34: 2395 | T34: 0 | U34: 0 | V34: 0 | W34: 0 | X34: 0 | Y34: 0 | Z34: 0 | AA34: =SUMIF([1]SA007!$C:$C,'SA007 2025.01-2026.05 '!$D34,[1]SA007!P:P) -> 0 | AB34: =SUMIF([1]SA007!$C:$C,'SA007 2025.01-2026.05 '!$D34,[1]SA007!Q:Q) -> 0 | AC34: =SUM(L34:AB34) -> 6166 | AD34: =AVERAGE(L34:AB34) -> 362.70588 | AG34: =SUMIF([1]SO003!$H:$H,'SA007 2025.01-2026.05 '!$D34,[1]SO003!AF:AF) -> 0 | AH34: =SUMIF([1]SO003!$H:$H,'SA007 2025.01-2026.05 '!$D34,[1]SO003!AH:AH) -> 0 | AI34: =SUMIF([1]SO003!$H:$H,'SA007 2025.01-2026.05 '!$D34,[1]SO003!AJ:AJ) -> 0
A35: HC340LA_0.6_1120_BAOSHAN | B35: HC340LA | C35: HC340LA | D35: 0.6X556X561 | E35: WISDOM AUTO 1 | F35: WISDOM AUTO 1 | G35: CR | H35: HC340LA | I35: 0.6 | J35: 556 | K35: 561 | L35: 12414 | M35: 18492 | N35: 17067 | O35: 9855 | P35: 17067 | Q35: 17047 | R35: 17033 | S35: 16993 | T35: 17050 | U35: 18452 | V35: 15294 | W35: 10040 | X35: 13514 | Y35: 14899 | Z35: 16438 | AA35: =SUMIF([1]SA007!$C:$C,'SA007 2025.01-2026.05 '!$D35,[1]SA007!P:P) -> 9984 | AB35: =SUMIF([1]SA007!$C:$C,'SA007 2025.01-2026.05 '!$D35,[1]SA007!Q:Q) -> 6999 | AC35: =SUM(L35:AB35) -> 248638 | AD35: =AVERAGE(L35:AB35) -> 14625.765 | AE35: เน้นผิวและคุณภาพ_x000D_ ห่อพลาสติกใส วางไม้พาเลท วาง 1 แถว_x000D_ แนบ INSPECTION DATA_x000D_ | AG35: =SUMIF([1]SO003!$H:$H,'SA007 2025.01-2026.05 '!$D35,[1]SO003!AF:AF) -> 11752.995 | AH35: =SUMIF([1]SO003!$H:$H,'SA007 2025.01-2026.05 '!$D35,[1]SO003!AH:AH) -> 11451.824 | AI35: =SUMIF([1]SO003!$H:$H,'SA007 2025.01-2026.05 '!$D35,[1]SO003!AJ:AJ) -> 301.17049
A36: SPCC-SD_0.7_1219_Common | B36: SPCC-SD | C36: SPCC-SD | D36: 0.70x55.00xCOIL | E36: GINFONG | F36: GINFONG | G36: CR | H36: SPCC-SD | I36: 0.7 | J36: 55 | K36: COIL | L36: 1120 | M36: 4104 | N36: 2152 | O36: 7288 | P36: 4790 | Q36: 2119 | R36: 3392 | S36: 7635 | T36: 3224 | U36: 4248 | V36: 4041 | W36: 4223 | X36: 6657 | Y36: 2763 | Z36: 9853 | AA36: =SUMIF([1]SA007!$C:$C,'SA007 2025.01-2026.05 '!$D36,[1]SA007!P:P) -> 0 | AB36: =SUMIF([1]SA007!$C:$C,'SA007 2025.01-2026.05 '!$D36,[1]SA007!Q:Q) -> 5223 | AC36: =SUM(L36:AB36) -> 72832 | AD36: =AVERAGE(L36:AB36) -> 4284.2353 | AE36: ลูกค้ารับน้ำหนักที่ 310-457 kg./ม้วน แนบ INSPECTION DATA_x000D__x000D_ ห่อพลาสติกใส ล้มวางไม้พาเลท 2 แถบ/เลท ไม้คั่น 40 มม. รัดสายเขียว 2 เส้น ครีบคว่ำ ครีบหงาย แยกพาเลท ครีบคว่ำ ครีบหงาย แยกพาเลท FG ระบุพาเลทและคีบคว่ำหงายลง Remark ในระบบด้วย | AG36: =SUMIF([1]SO003!$H:$H,'SA007 2025.01-2026.05 '!$D36,[1]SO003!AF:AF) -> 10000 | AH36: =SUMIF([1]SO003!$H:$H,'SA007 2025.01-2026.05 '!$D36,[1]SO003!AH:AH) -> 4685 | AI36: =SUMIF([1]SO003!$H:$H,'SA007 2025.01-2026.05 '!$D36,[1]SO003!AJ:AJ) -> 5315
A37: SPCC-SD_0.7_1219_Common | B37: SPCC-SD | C37: SPCC-SD | D37: 0.7X210X570 | E37: SAN HO PRECISION | F37: SAN HO PRECISION | G37: CR | H37: SPCC | I37: 0.7 | J37: 210 | K37: 570 | L37: 0 | M37: 382 | N37: 0 | O37: 0 | P37: 0 | Q37: 0 | R37: 0 | S37: 0 | T37: 0 | U37: 0 | V37: 0 | W37: 0 | X37: 0 | Y37: 0 | Z37: 0 | AA37: =SUMIF([1]SA007!$C:$C,'SA007 2025.01-2026.05 '!$D37,[1]SA007!P:P) -> 1091 | AB37: =SUMIF([1]SA007!$C:$C,'SA007 2025.01-2026.05 '!$D37,[1]SA007!Q:Q) -> 0 | AC37: =SUM(L37:AB37) -> 1473 | AD37: =AVERAGE(L37:AB37) -> 86.647059 | AG37: =SUMIF([1]SO003!$H:$H,'SA007 2025.01-2026.05 '!$D37,[1]SO003!AF:AF) -> 0 | AH37: =SUMIF([1]SO003!$H:$H,'SA007 2025.01-2026.05 '!$D37,[1]SO003!AH:AH) -> 0 | AI37: =SUMIF([1]SO003!$H:$H,'SA007 2025.01-2026.05 '!$D37,[1]SO003!AJ:AJ) -> 0
A38: SPCC-SD_0.8_1219_Common | B38: SPCC-SD | C38: SPCC-SD | D38: 0.80x83.00xCOIL | E38: GINFONG | F38: GINFONG | G38: CR | H38: SPCC-SD | I38: 0.8 | J38: 83 | K38: COIL | L38: 0 | M38: 620 | N38: 0 | O38: 0 | P38: 0 | Q38: 0 | R38: 0 | S38: 734 | T38: 0 | U38: 0 | V38: 0 | W38: 0 | X38: 0 | Y38: 0 | Z38: 0 | AA38: =SUMIF([1]SA007!$C:$C,'SA007 2025.01-2026.05 '!$D38,[1]SA007!P:P) -> 0 | AB38: =SUMIF([1]SA007!$C:$C,'SA007 2025.01-2026.05 '!$D38,[1]SA007!Q:Q) -> 0 | AC38: =SUM(L38:AB38) -> 1354 | AD38: =AVERAGE(L38:AB38) -> 79.647059 | AE38: ห่อพลาสติกใส ล้มวางไม้พาเลท 5 แถบ/พาเลท ** มีไม้คั่น **_x000D_ แนบ INSPECTION DATA_x000D_ รัดสายเขียว 2 เส้น ครีบคว่ำ ครีบหงาย แยกพาเลท_x000D_ ครีบคว่ำ ครีบหงาย แยกพาเลท FG ระบุพาเลทและคีบคว่ำหงายลง Remark ในระบบด้วย | AG38: =SUMIF([1]SO003!$H:$H,'SA007 2025.01-2026.05 '!$D38,[1]SO003!AF:AF) -> 0 | AH38: =SUMIF([1]SO003!$H:$H,'SA007 2025.01-2026.05 '!$D38,[1]SO003!AH:AH) -> 0 | AI38: =SUMIF([1]SO003!$H:$H,'SA007 2025.01-2026.05 '!$D38,[1]SO003!AJ:AJ) -> 0
A39: SECC-16/16_0.8_1219_Common | B39: SECC-20/20 | C39: SECC-20/20 | D39: 0.800X50.00X1219.00 | E39: AAA MANU | F39: AAA MANU | G39: EG | H39: SECC-F20 | I39: 0.8 | J39: 50 | K39: 1219 | L39: 0 | M39: 70 | N39: 108 | O39: 108 | P39: 0 | Q39: 0 | R39: 0 | S39: 0 | T39: 0 | U39: 0 | V39: 0 | W39: 0 | X39: 36 | Y39: 0 | Z39: 0 | AA39: =SUMIF([1]SA007!$C:$C,'SA007 2025.01-2026.05 '!$D39,[1]SA007!P:P) -> 0 | AB39: =SUMIF([1]SA007!$C:$C,'SA007 2025.01-2026.05 '!$D39,[1]SA007!Q:Q) -> 0 | AC39: =SUM(L39:AB39) -> 322 | AD39: =AVERAGE(L39:AB39) -> 18.941176 | AE39: ห่อพลาสติกใส วางพาเลทไม้ | AG39: =SUMIF([1]SO003!$H:$H,'SA007 2025.01-2026.05 '!$D39,[1]SO003!AF:AF) -> 0 | AH39: =SUMIF([1]SO003!$H:$H,'SA007 2025.01-2026.05 '!$D39,[1]SO003!AH:AH) -> 0 | AI39: =SUMIF([1]SO003!$H:$H,'SA007 2025.01-2026.05 '!$D39,[1]SO003!AJ:AJ) -> 0
A40: SGCC-Z22_0.5_1219_Common | B40: SGCC-Z18 | C40: SGCC-Z18 | D40: SGUR-0006-(44) | E40: UKKARIT | F40: UKKARIT | G40: GI | H40: GI/SGCC-Z18/Z22 | I40: 0.5 | J40: 175 | K40: 1135 | L40: 229 | M40: 237 | N40: 0 | O40: 0 | P40: 0 | Q40: 245 | R40: 0 | S40: 0 | T40: 0 | U40: 0 | V40: 127 | W40: 0 | X40: 0 | Y40: 0 | Z40: 398 | AA40: =SUMIF([1]SA007!$C:$C,'SA007 2025.01-2026.05 '!$D40,[1]SA007!P:P) -> 0 | AB40: =SUMIF([1]SA007!$C:$C,'SA007 2025.01-2026.05 '!$D40,[1]SA007!Q:Q) -> 0 | AC40: =SUM(L40:AB40) -> 1236 | AD40: =AVERAGE(L40:AB40) -> 72.705882 | AE40: เน้นผิวและคุณภาพ_x000D_ แนบINSPECTION_x000D_ ห่อพลาสติกใส วางไม้พาเลท | AG40: =SUMIF([1]SO003!$H:$H,'SA007 2025.01-2026.05 '!$D40,[1]SO003!AF:AF) -> 0 | AH40: =SUMIF([1]SO003!$H:$H,'SA007 2025.01-2026.05 '!$D40,[1]SO003!AH:AH) -> 0 | AI40: =SUMIF([1]SO003!$H:$H,'SA007 2025.01-2026.05 '!$D40,[1]SO003!AJ:AJ) -> 0
...
